[
  {
    "url": "https://api.github.com/repos/pandas-dev/pandas/issues/comments/106716752",
    "html_url": "https://github.com/pandas-dev/pandas/issues/10227#issuecomment-106716752",
    "issue_url": "https://api.github.com/repos/pandas-dev/pandas/issues/10227",
    "id": 106716752,
    "node_id": "MDEyOklzc3VlQ29tbWVudDEwNjcxNjc1Mg==",
    "user": {
      "login": "jorisvandenbossche",
      "id": 1020496,
      "node_id": "MDQ6VXNlcjEwMjA0OTY=",
      "avatar_url": "https://avatars2.githubusercontent.com/u/1020496?v=4",
      "gravatar_id": "",
      "url": "https://api.github.com/users/jorisvandenbossche",
      "html_url": "https://github.com/jorisvandenbossche",
      "followers_url": "https://api.github.com/users/jorisvandenbossche/followers",
      "following_url": "https://api.github.com/users/jorisvandenbossche/following{/other_user}",
      "gists_url": "https://api.github.com/users/jorisvandenbossche/gists{/gist_id}",
      "starred_url": "https://api.github.com/users/jorisvandenbossche/starred{/owner}{/repo}",
      "subscriptions_url": "https://api.github.com/users/jorisvandenbossche/subscriptions",
      "organizations_url": "https://api.github.com/users/jorisvandenbossche/orgs",
      "repos_url": "https://api.github.com/users/jorisvandenbossche/repos",
      "events_url": "https://api.github.com/users/jorisvandenbossche/events{/privacy}",
      "received_events_url": "https://api.github.com/users/jorisvandenbossche/received_events",
      "type": "User",
      "site_admin": false
    },
    "created_at": "2015-05-29T07:05:49Z",
    "updated_at": "2015-05-29T07:05:49Z",
    "author_association": "MEMBER",
    "body": "@shadow-identity You will have to provide some more details ..\n\nE.g. provide some example data that reproduces the error. How does `cStringIO.StringIO(self.report.body)` look like?\n"
  },
  {
    "url": "https://api.github.com/repos/pandas-dev/pandas/issues/comments/106884081",
    "html_url": "https://github.com/pandas-dev/pandas/issues/10227#issuecomment-106884081",
    "issue_url": "https://api.github.com/repos/pandas-dev/pandas/issues/10227",
    "id": 106884081,
    "node_id": "MDEyOklzc3VlQ29tbWVudDEwNjg4NDA4MQ==",
    "user": {
      "login": "shadow-identity",
      "id": 1223112,
      "node_id": "MDQ6VXNlcjEyMjMxMTI=",
      "avatar_url": "https://avatars2.githubusercontent.com/u/1223112?v=4",
      "gravatar_id": "",
      "url": "https://api.github.com/users/shadow-identity",
      "html_url": "https://github.com/shadow-identity",
      "followers_url": "https://api.github.com/users/shadow-identity/followers",
      "following_url": "https://api.github.com/users/shadow-identity/following{/other_user}",
      "gists_url": "https://api.github.com/users/shadow-identity/gists{/gist_id}",
      "starred_url": "https://api.github.com/users/shadow-identity/starred{/owner}{/repo}",
      "subscriptions_url": "https://api.github.com/users/shadow-identity/subscriptions",
      "organizations_url": "https://api.github.com/users/shadow-identity/orgs",
      "repos_url": "https://api.github.com/users/shadow-identity/repos",
      "events_url": "https://api.github.com/users/shadow-identity/events{/privacy}",
      "received_events_url": "https://api.github.com/users/shadow-identity/received_events",
      "type": "User",
      "site_admin": false
    },
    "created_at": "2015-05-29T17:45:38Z",
    "updated_at": "2015-05-29T17:45:38Z",
    "author_association": "NONE",
    "body": "@jorisvandenbossche `self.report.body` is just a blank string (`''`)\n`cStringIO.StringIO` returns file-like object from string\nSo exception raises only when file is blank. In other cases (`self.report.body` contains csv) all works fine. \nIt is unexpected for me because with 0.14.1 exception not raises. \n"
  },
  {
    "url": "https://api.github.com/repos/pandas-dev/pandas/issues/comments/106958109",
    "html_url": "https://github.com/pandas-dev/pandas/issues/10227#issuecomment-106958109",
    "issue_url": "https://api.github.com/repos/pandas-dev/pandas/issues/10227",
    "id": 106958109,
    "node_id": "MDEyOklzc3VlQ29tbWVudDEwNjk1ODEwOQ==",
    "user": {
      "login": "jreback",
      "id": 953992,
      "node_id": "MDQ6VXNlcjk1Mzk5Mg==",
      "avatar_url": "https://avatars2.githubusercontent.com/u/953992?v=4",
      "gravatar_id": "",
      "url": "https://api.github.com/users/jreback",
      "html_url": "https://github.com/jreback",
      "followers_url": "https://api.github.com/users/jreback/followers",
      "following_url": "https://api.github.com/users/jreback/following{/other_user}",
      "gists_url": "https://api.github.com/users/jreback/gists{/gist_id}",
      "starred_url": "https://api.github.com/users/jreback/starred{/owner}{/repo}",
      "subscriptions_url": "https://api.github.com/users/jreback/subscriptions",
      "organizations_url": "https://api.github.com/users/jreback/orgs",
      "repos_url": "https://api.github.com/users/jreback/repos",
      "events_url": "https://api.github.com/users/jreback/events{/privacy}",
      "received_events_url": "https://api.github.com/users/jreback/received_events",
      "type": "User",
      "site_admin": false
    },
    "created_at": "2015-05-29T23:30:39Z",
    "updated_at": "2015-05-29T23:30:39Z",
    "author_association": "CONTRIBUTOR",
    "body": "This raises in 0.14.1 as well. `CParserError: Passed header=0 but only 0 lines in file`. So this is correct.\n"
  },
  {
    "url": "https://api.github.com/repos/pandas-dev/pandas/issues/comments/106975253",
    "html_url": "https://github.com/pandas-dev/pandas/issues/10227#issuecomment-106975253",
    "issue_url": "https://api.github.com/repos/pandas-dev/pandas/issues/10227",
    "id": 106975253,
    "node_id": "MDEyOklzc3VlQ29tbWVudDEwNjk3NTI1Mw==",
    "user": {
      "login": "shadow-identity",
      "id": 1223112,
      "node_id": "MDQ6VXNlcjEyMjMxMTI=",
      "avatar_url": "https://avatars2.githubusercontent.com/u/1223112?v=4",
      "gravatar_id": "",
      "url": "https://api.github.com/users/shadow-identity",
      "html_url": "https://github.com/shadow-identity",
      "followers_url": "https://api.github.com/users/shadow-identity/followers",
      "following_url": "https://api.github.com/users/shadow-identity/following{/other_user}",
      "gists_url": "https://api.github.com/users/shadow-identity/gists{/gist_id}",
      "starred_url": "https://api.github.com/users/shadow-identity/starred{/owner}{/repo}",
      "subscriptions_url": "https://api.github.com/users/shadow-identity/subscriptions",
      "organizations_url": "https://api.github.com/users/shadow-identity/orgs",
      "repos_url": "https://api.github.com/users/shadow-identity/repos",
      "events_url": "https://api.github.com/users/shadow-identity/events{/privacy}",
      "received_events_url": "https://api.github.com/users/shadow-identity/received_events",
      "type": "User",
      "site_admin": false
    },
    "created_at": "2015-05-30T02:13:05Z",
    "updated_at": "2015-05-30T02:13:05Z",
    "author_association": "NONE",
    "body": "@jorisvandenbossche I'm using this code:\n\n```\n        try:\n            self.data = pandas.read_csv(cStringIO.StringIO(self.report.body))\n        except CParserError as e:\n            raise formbuilder_core.views.ValidationException('report', 'insufficient')\n```\n\nAnd I need to just install 0.14.1 back to disappear exception I've reported...\n"
  },
  {
    "url": "https://api.github.com/repos/pandas-dev/pandas/issues/comments/107146065",
    "html_url": "https://github.com/pandas-dev/pandas/issues/10227#issuecomment-107146065",
    "issue_url": "https://api.github.com/repos/pandas-dev/pandas/issues/10227",
    "id": 107146065,
    "node_id": "MDEyOklzc3VlQ29tbWVudDEwNzE0NjA2NQ==",
    "user": {
      "login": "jorisvandenbossche",
      "id": 1020496,
      "node_id": "MDQ6VXNlcjEwMjA0OTY=",
      "avatar_url": "https://avatars2.githubusercontent.com/u/1020496?v=4",
      "gravatar_id": "",
      "url": "https://api.github.com/users/jorisvandenbossche",
      "html_url": "https://github.com/jorisvandenbossche",
      "followers_url": "https://api.github.com/users/jorisvandenbossche/followers",
      "following_url": "https://api.github.com/users/jorisvandenbossche/following{/other_user}",
      "gists_url": "https://api.github.com/users/jorisvandenbossche/gists{/gist_id}",
      "starred_url": "https://api.github.com/users/jorisvandenbossche/starred{/owner}{/repo}",
      "subscriptions_url": "https://api.github.com/users/jorisvandenbossche/subscriptions",
      "organizations_url": "https://api.github.com/users/jorisvandenbossche/orgs",
      "repos_url": "https://api.github.com/users/jorisvandenbossche/repos",
      "events_url": "https://api.github.com/users/jorisvandenbossche/events{/privacy}",
      "received_events_url": "https://api.github.com/users/jorisvandenbossche/received_events",
      "type": "User",
      "site_admin": false
    },
    "created_at": "2015-05-31T08:43:51Z",
    "updated_at": "2015-05-31T08:43:51Z",
    "author_association": "MEMBER",
    "body": "Ah, so it seems the exception type has changed from CParseError to ValueError. So you can probably catch both to have the code work for both pandas versions\n"
  },
  {
    "url": "https://api.github.com/repos/pandas-dev/pandas/issues/comments/144473961",
    "html_url": "https://github.com/pandas-dev/pandas/issues/10227#issuecomment-144473961",
    "issue_url": "https://api.github.com/repos/pandas-dev/pandas/issues/10227",
    "id": 144473961,
    "node_id": "MDEyOklzc3VlQ29tbWVudDE0NDQ3Mzk2MQ==",
    "user": {
      "login": "szeitlin",
      "id": 5185401,
      "node_id": "MDQ6VXNlcjUxODU0MDE=",
      "avatar_url": "https://avatars0.githubusercontent.com/u/5185401?v=4",
      "gravatar_id": "",
      "url": "https://api.github.com/users/szeitlin",
      "html_url": "https://github.com/szeitlin",
      "followers_url": "https://api.github.com/users/szeitlin/followers",
      "following_url": "https://api.github.com/users/szeitlin/following{/other_user}",
      "gists_url": "https://api.github.com/users/szeitlin/gists{/gist_id}",
      "starred_url": "https://api.github.com/users/szeitlin/starred{/owner}{/repo}",
      "subscriptions_url": "https://api.github.com/users/szeitlin/subscriptions",
      "organizations_url": "https://api.github.com/users/szeitlin/orgs",
      "repos_url": "https://api.github.com/users/szeitlin/repos",
      "events_url": "https://api.github.com/users/szeitlin/events{/privacy}",
      "received_events_url": "https://api.github.com/users/szeitlin/received_events",
      "type": "User",
      "site_admin": false
    },
    "created_at": "2015-09-30T16:52:04Z",
    "updated_at": "2015-09-30T16:52:04Z",
    "author_association": "NONE",
    "body": "Yeah I'm noticing something similar, but even more strange. If I try to read the file and it fails, once that exception is raised, I can't get it to work even with the correct parameters. However, if I independently read the file with the correct parameters, it does work. It's like it won't let go of the exception once it's raised (?). e.g. this works, so I know there's nothing wrong with my file:\n\n`pd.read_csv('myfile.csv', header=4)`\n\nbut this doesn't work:\n\n```\n     try:\n         one = pd.read_csv(csvfile)\n     except CParserError as e:                          #it is catching the error\n         two = pd.read_csv(csvfile, header=4)         #this fails\n```\n\nBut it used to work with very similar code (in version 15.1):\n\n```\n        try:\n           df = pd.read_csv(fullpath)\n           print(\"successfully read file named \" + filename)\n       except pd.parser.CParserError as e:\n           print(\"parser error, I'll try again\")\n           try:\n               df = pd.read_csv(fullpath, skiprows=4)\n               print(\"successfully read file named \" + filename)\n           except Exception as e:\n               raise FileTypeUnknownError\n               print(type(e))\n```\n\n(note that I also tried to catch it as a ValueError, but it still fails with \"No columns to parse from file\")\n"
  }
]
