[
  {
    "url": "https://api.github.com/repos/pandas-dev/pandas/issues/comments/345237485",
    "html_url": "https://github.com/pandas-dev/pandas/issues/18344#issuecomment-345237485",
    "issue_url": "https://api.github.com/repos/pandas-dev/pandas/issues/18344",
    "id": 345237485,
    "node_id": "MDEyOklzc3VlQ29tbWVudDM0NTIzNzQ4NQ==",
    "user": {
      "login": "TomAugspurger",
      "id": 1312546,
      "node_id": "MDQ6VXNlcjEzMTI1NDY=",
      "avatar_url": "https://avatars3.githubusercontent.com/u/1312546?v=4",
      "gravatar_id": "",
      "url": "https://api.github.com/users/TomAugspurger",
      "html_url": "https://github.com/TomAugspurger",
      "followers_url": "https://api.github.com/users/TomAugspurger/followers",
      "following_url": "https://api.github.com/users/TomAugspurger/following{/other_user}",
      "gists_url": "https://api.github.com/users/TomAugspurger/gists{/gist_id}",
      "starred_url": "https://api.github.com/users/TomAugspurger/starred{/owner}{/repo}",
      "subscriptions_url": "https://api.github.com/users/TomAugspurger/subscriptions",
      "organizations_url": "https://api.github.com/users/TomAugspurger/orgs",
      "repos_url": "https://api.github.com/users/TomAugspurger/repos",
      "events_url": "https://api.github.com/users/TomAugspurger/events{/privacy}",
      "received_events_url": "https://api.github.com/users/TomAugspurger/received_events",
      "type": "User",
      "site_admin": false
    },
    "created_at": "2017-11-17T12:59:16Z",
    "updated_at": "2017-11-17T12:59:16Z",
    "author_association": "CONTRIBUTOR",
    "body": "So, IIUC the issue is with matplotlib's AutoDateLocator not understanding DatetimeIndexes, correct?\r\n\r\nThat's not too surprising, since they don't depend on pandas. We provide our own locators / formatters for our dtypes, which is why the default `.plot` should work."
  },
  {
    "url": "https://api.github.com/repos/pandas-dev/pandas/issues/comments/345253611",
    "html_url": "https://github.com/pandas-dev/pandas/issues/18344#issuecomment-345253611",
    "issue_url": "https://api.github.com/repos/pandas-dev/pandas/issues/18344",
    "id": 345253611,
    "node_id": "MDEyOklzc3VlQ29tbWVudDM0NTI1MzYxMQ==",
    "user": {
      "login": "sakurai-youhei",
      "id": 721858,
      "node_id": "MDQ6VXNlcjcyMTg1OA==",
      "avatar_url": "https://avatars3.githubusercontent.com/u/721858?v=4",
      "gravatar_id": "",
      "url": "https://api.github.com/users/sakurai-youhei",
      "html_url": "https://github.com/sakurai-youhei",
      "followers_url": "https://api.github.com/users/sakurai-youhei/followers",
      "following_url": "https://api.github.com/users/sakurai-youhei/following{/other_user}",
      "gists_url": "https://api.github.com/users/sakurai-youhei/gists{/gist_id}",
      "starred_url": "https://api.github.com/users/sakurai-youhei/starred{/owner}{/repo}",
      "subscriptions_url": "https://api.github.com/users/sakurai-youhei/subscriptions",
      "organizations_url": "https://api.github.com/users/sakurai-youhei/orgs",
      "repos_url": "https://api.github.com/users/sakurai-youhei/repos",
      "events_url": "https://api.github.com/users/sakurai-youhei/events{/privacy}",
      "received_events_url": "https://api.github.com/users/sakurai-youhei/received_events",
      "type": "User",
      "site_admin": false
    },
    "created_at": "2017-11-17T14:11:03Z",
    "updated_at": "2017-11-17T14:11:03Z",
    "author_association": "NONE",
    "body": "Yes, it is probably. But I don’t have clear idea of what’s root cause basically; Moreover, I’m not familiar with Pandas nor matplotlib.\r\n\r\nDo you mean it’s not issue in Pandas but in my usage of non-Pandas locator with Pandas? Or is it rather problem in matplotlib?\r\n\r\nThanks."
  },
  {
    "url": "https://api.github.com/repos/pandas-dev/pandas/issues/comments/345255896",
    "html_url": "https://github.com/pandas-dev/pandas/issues/18344#issuecomment-345255896",
    "issue_url": "https://api.github.com/repos/pandas-dev/pandas/issues/18344",
    "id": 345255896,
    "node_id": "MDEyOklzc3VlQ29tbWVudDM0NTI1NTg5Ng==",
    "user": {
      "login": "sakurai-youhei",
      "id": 721858,
      "node_id": "MDQ6VXNlcjcyMTg1OA==",
      "avatar_url": "https://avatars3.githubusercontent.com/u/721858?v=4",
      "gravatar_id": "",
      "url": "https://api.github.com/users/sakurai-youhei",
      "html_url": "https://github.com/sakurai-youhei",
      "followers_url": "https://api.github.com/users/sakurai-youhei/followers",
      "following_url": "https://api.github.com/users/sakurai-youhei/following{/other_user}",
      "gists_url": "https://api.github.com/users/sakurai-youhei/gists{/gist_id}",
      "starred_url": "https://api.github.com/users/sakurai-youhei/starred{/owner}{/repo}",
      "subscriptions_url": "https://api.github.com/users/sakurai-youhei/subscriptions",
      "organizations_url": "https://api.github.com/users/sakurai-youhei/orgs",
      "repos_url": "https://api.github.com/users/sakurai-youhei/repos",
      "events_url": "https://api.github.com/users/sakurai-youhei/events{/privacy}",
      "received_events_url": "https://api.github.com/users/sakurai-youhei/received_events",
      "type": "User",
      "site_admin": false
    },
    "created_at": "2017-11-17T14:20:15Z",
    "updated_at": "2017-11-17T14:21:03Z",
    "author_association": "NONE",
    "body": "As I found https://github.com/pandas-dev/pandas/blob/c3cfe90d8b7be9435c59f279fc933c7931f0e215/pandas/plotting/_converter.py, it is probably caused by my fault. I’ll close this issue after playing locators there. Thanks."
  },
  {
    "url": "https://api.github.com/repos/pandas-dev/pandas/issues/comments/345271245",
    "html_url": "https://github.com/pandas-dev/pandas/issues/18344#issuecomment-345271245",
    "issue_url": "https://api.github.com/repos/pandas-dev/pandas/issues/18344",
    "id": 345271245,
    "node_id": "MDEyOklzc3VlQ29tbWVudDM0NTI3MTI0NQ==",
    "user": {
      "login": "TomAugspurger",
      "id": 1312546,
      "node_id": "MDQ6VXNlcjEzMTI1NDY=",
      "avatar_url": "https://avatars3.githubusercontent.com/u/1312546?v=4",
      "gravatar_id": "",
      "url": "https://api.github.com/users/TomAugspurger",
      "html_url": "https://github.com/TomAugspurger",
      "followers_url": "https://api.github.com/users/TomAugspurger/followers",
      "following_url": "https://api.github.com/users/TomAugspurger/following{/other_user}",
      "gists_url": "https://api.github.com/users/TomAugspurger/gists{/gist_id}",
      "starred_url": "https://api.github.com/users/TomAugspurger/starred{/owner}{/repo}",
      "subscriptions_url": "https://api.github.com/users/TomAugspurger/subscriptions",
      "organizations_url": "https://api.github.com/users/TomAugspurger/orgs",
      "repos_url": "https://api.github.com/users/TomAugspurger/repos",
      "events_url": "https://api.github.com/users/TomAugspurger/events{/privacy}",
      "received_events_url": "https://api.github.com/users/TomAugspurger/received_events",
      "type": "User",
      "site_admin": false
    },
    "created_at": "2017-11-17T15:16:20Z",
    "updated_at": "2017-11-17T15:16:20Z",
    "author_association": "CONTRIBUTOR",
    "body": "> Do you mean it’s not issue in Pandas but in my usage of non-Pandas locator with Pandas? Or is it rather problem in matplotlib?\r\n\r\nBoth :) I suspect matplotlib's AutoDateLocator doesn't know how to deal with pandas' datetimes. Though there has been some work there recently, so maybe try with matplotlib master: https://github.com/matplotlib/matplotlib/pull/9794/files"
  },
  {
    "url": "https://api.github.com/repos/pandas-dev/pandas/issues/comments/345487424",
    "html_url": "https://github.com/pandas-dev/pandas/issues/18344#issuecomment-345487424",
    "issue_url": "https://api.github.com/repos/pandas-dev/pandas/issues/18344",
    "id": 345487424,
    "node_id": "MDEyOklzc3VlQ29tbWVudDM0NTQ4NzQyNA==",
    "user": {
      "login": "sakurai-youhei",
      "id": 721858,
      "node_id": "MDQ6VXNlcjcyMTg1OA==",
      "avatar_url": "https://avatars3.githubusercontent.com/u/721858?v=4",
      "gravatar_id": "",
      "url": "https://api.github.com/users/sakurai-youhei",
      "html_url": "https://github.com/sakurai-youhei",
      "followers_url": "https://api.github.com/users/sakurai-youhei/followers",
      "following_url": "https://api.github.com/users/sakurai-youhei/following{/other_user}",
      "gists_url": "https://api.github.com/users/sakurai-youhei/gists{/gist_id}",
      "starred_url": "https://api.github.com/users/sakurai-youhei/starred{/owner}{/repo}",
      "subscriptions_url": "https://api.github.com/users/sakurai-youhei/subscriptions",
      "organizations_url": "https://api.github.com/users/sakurai-youhei/orgs",
      "repos_url": "https://api.github.com/users/sakurai-youhei/repos",
      "events_url": "https://api.github.com/users/sakurai-youhei/events{/privacy}",
      "received_events_url": "https://api.github.com/users/sakurai-youhei/received_events",
      "type": "User",
      "site_admin": false
    },
    "created_at": "2017-11-19T02:43:34Z",
    "updated_at": "2017-11-19T02:51:13Z",
    "author_association": "NONE",
    "body": "Neither helps, PandasAutoDateLocator nor matplotlib from master branch...\r\n\r\n```python\r\nfrom datetime import datetime\r\nfrom matplotlib import pyplot as plt\r\nimport pandas as pd\r\nfrom pandas.tseries.converter import PandasAutoDateLocator\r\n\r\nN = 2\r\nindex = pd.date_range(\r\n    datetime.now().replace(second=0, microsecond=0),\r\n    periods=N,\r\n    freq='60Min',\r\n)\r\n\r\ndf = pd.DataFrame({\"A\": range(N)}, index)\r\nax = df.plot()\r\nax.xaxis.set_major_locator(PandasAutoDateLocator())\r\n\r\nprint(df)\r\nplt.show()\r\n```\r\n\r\n```\r\nException in Tkinter callback\r\nTraceback (most recent call last):\r\n  File \"/usr/local/lib/python3.6/tkinter/__init__.py\", line 1699, in __call__\r\n    return self.func(*args)\r\n  File \"/usr/local/lib/python3.6/tkinter/__init__.py\", line 745, in callit\r\n    func(*args)\r\n  File \"/usr/local/lib/python3.6/site-packages/matplotlib/backends/backend_tkagg.py\", line 324, in idle_draw\r\n    self.draw()\r\n  File \"/usr/local/lib/python3.6/site-packages/matplotlib/backends/backend_tkagg.py\", line 305, in draw\r\n    FigureCanvasAgg.draw(self)\r\n  File \"/usr/local/lib/python3.6/site-packages/matplotlib/backends/backend_agg.py\", line 427, in draw\r\n    self.figure.draw(self.renderer)\r\n  File \"/usr/local/lib/python3.6/site-packages/matplotlib/artist.py\", line 55, in draw_wrapper\r\n    return draw(artist, renderer, *args, **kwargs)\r\n  File \"/usr/local/lib/python3.6/site-packages/matplotlib/figure.py\", line 1327, in draw\r\n    renderer, self, artists, self.suppressComposite)\r\n  File \"/usr/local/lib/python3.6/site-packages/matplotlib/image.py\", line 138, in _draw_list_compositing_images\r\n    a.draw(renderer)\r\n  File \"/usr/local/lib/python3.6/site-packages/matplotlib/artist.py\", line 55, in draw_wrapper\r\n    return draw(artist, renderer, *args, **kwargs)\r\n  File \"/usr/local/lib/python3.6/site-packages/matplotlib/axes/_base.py\", line 2448, in draw\r\n    mimage._draw_list_compositing_images(renderer, self, artists)\r\n  File \"/usr/local/lib/python3.6/site-packages/matplotlib/image.py\", line 138, in _draw_list_compositing_images\r\n    a.draw(renderer)\r\n  File \"/usr/local/lib/python3.6/site-packages/matplotlib/artist.py\", line 55, in draw_wrapper\r\n    return draw(artist, renderer, *args, **kwargs)\r\n  File \"/usr/local/lib/python3.6/site-packages/matplotlib/axis.py\", line 1134, in draw\r\n    ticks_to_draw = self._update_ticks(renderer)\r\n  File \"/usr/local/lib/python3.6/site-packages/matplotlib/axis.py\", line 974, in _update_ticks\r\n    tick_tups = list(self.iter_ticks())\r\n  File \"/usr/local/lib/python3.6/site-packages/matplotlib/axis.py\", line 917, in iter_ticks\r\n    majorLocs = self.major.locator()\r\n  File \"/usr/local/lib/python3.6/site-packages/matplotlib/dates.py\", line 1088, in __call__\r\n    self.refresh()\r\n  File \"/usr/local/lib/python3.6/site-packages/matplotlib/dates.py\", line 1108, in refresh\r\n    dmin, dmax = self.viewlim_to_dt()\r\n  File \"/usr/local/lib/python3.6/site-packages/matplotlib/dates.py\", line 866, in viewlim_to_dt\r\n    return num2date(vmin, self.tz), num2date(vmax, self.tz)\r\n  File \"/usr/local/lib/python3.6/site-packages/matplotlib/dates.py\", line 471, in num2date\r\n    return _from_ordinalf(x, tz)\r\n  File \"/usr/local/lib/python3.6/site-packages/matplotlib/dates.py\", line 281, in _from_ordinalf\r\n    dt = datetime.datetime.fromordinal(ix).replace(tzinfo=UTC)\r\nValueError: year 68953 is out of range\r\nException in Tkinter callback\r\nTraceback (most recent call last):\r\n  File \"/usr/local/lib/python3.6/tkinter/__init__.py\", line 1699, in __call__\r\n    return self.func(*args)\r\n  File \"/usr/local/lib/python3.6/site-packages/matplotlib/backends/backend_tkagg.py\", line 234, in resize\r\n    self.show()\r\n  File \"/usr/local/lib/python3.6/site-packages/matplotlib/backends/backend_tkagg.py\", line 305, in draw\r\n    FigureCanvasAgg.draw(self)\r\n  File \"/usr/local/lib/python3.6/site-packages/matplotlib/backends/backend_agg.py\", line 427, in draw\r\n    self.figure.draw(self.renderer)\r\n  File \"/usr/local/lib/python3.6/site-packages/matplotlib/artist.py\", line 55, in draw_wrapper\r\n    return draw(artist, renderer, *args, **kwargs)\r\n  File \"/usr/local/lib/python3.6/site-packages/matplotlib/figure.py\", line 1327, in draw\r\n    renderer, self, artists, self.suppressComposite)\r\n  File \"/usr/local/lib/python3.6/site-packages/matplotlib/image.py\", line 138, in _draw_list_compositing_images\r\n    a.draw(renderer)\r\n  File \"/usr/local/lib/python3.6/site-packages/matplotlib/artist.py\", line 55, in draw_wrapper\r\n    return draw(artist, renderer, *args, **kwargs)\r\n  File \"/usr/local/lib/python3.6/site-packages/matplotlib/axes/_base.py\", line 2448, in draw\r\n    mimage._draw_list_compositing_images(renderer, self, artists)\r\n  File \"/usr/local/lib/python3.6/site-packages/matplotlib/image.py\", line 138, in _draw_list_compositing_images\r\n    a.draw(renderer)\r\n  File \"/usr/local/lib/python3.6/site-packages/matplotlib/artist.py\", line 55, in draw_wrapper\r\n    return draw(artist, renderer, *args, **kwargs)\r\n  File \"/usr/local/lib/python3.6/site-packages/matplotlib/axis.py\", line 1134, in draw\r\n    ticks_to_draw = self._update_ticks(renderer)\r\n  File \"/usr/local/lib/python3.6/site-packages/matplotlib/axis.py\", line 974, in _update_ticks\r\n    tick_tups = list(self.iter_ticks())\r\n  File \"/usr/local/lib/python3.6/site-packages/matplotlib/axis.py\", line 917, in iter_ticks\r\n    majorLocs = self.major.locator()\r\n  File \"/usr/local/lib/python3.6/site-packages/matplotlib/dates.py\", line 1088, in __call__\r\n    self.refresh()\r\n  File \"/usr/local/lib/python3.6/site-packages/matplotlib/dates.py\", line 1108, in refresh\r\n    dmin, dmax = self.viewlim_to_dt()\r\n  File \"/usr/local/lib/python3.6/site-packages/matplotlib/dates.py\", line 866, in viewlim_to_dt\r\n    return num2date(vmin, self.tz), num2date(vmax, self.tz)\r\n  File \"/usr/local/lib/python3.6/site-packages/matplotlib/dates.py\", line 471, in num2date\r\n    return _from_ordinalf(x, tz)\r\n  File \"/usr/local/lib/python3.6/site-packages/matplotlib/dates.py\", line 281, in _from_ordinalf\r\n    dt = datetime.datetime.fromordinal(ix).replace(tzinfo=UTC)\r\nValueError: year 68953 is out of range\r\n```\r\n\r\n```\r\nroot@6d08a38f34e5:/# python -VV\r\nPython 3.6.3 (default, Nov  4 2017, 22:17:09)\r\n[GCC 4.9.2]\r\nroot@6d08a38f34e5:/# python -m pip freeze\r\ncycler==0.10.0\r\nmatplotlib==0+unknown\r\nnumpy==1.13.3\r\npandas==0.21.0\r\npyparsing==2.2.0\r\npython-dateutil==2.6.1\r\npytz==2017.3\r\nsix==1.11.0\r\nroot@6d08a38f34e5:/# python -c \"import matplotlib as mpl; print(mpl.__version__)\"\r\n0+unknown\r\nroot@6d08a38f34e5:/# python -c \"import pandas as pd; pd.show_versions()\"\r\n\r\nINSTALLED VERSIONS\r\n------------------\r\ncommit: None\r\npython: 3.6.3.final.0\r\npython-bits: 64\r\nOS: Linux\r\nOS-release: 4.9.49-moby\r\nmachine: x86_64\r\nprocessor:\r\nbyteorder: little\r\nLC_ALL: None\r\nLANG: C.UTF-8\r\nLOCALE: en_US.UTF-8\r\n\r\npandas: 0.21.0\r\npytest: None\r\npip: 9.0.1\r\nsetuptools: 36.6.0\r\nCython: None\r\nnumpy: 1.13.3\r\nscipy: None\r\npyarrow: None\r\nxarray: None\r\nIPython: None\r\nsphinx: None\r\npatsy: None\r\ndateutil: 2.6.1\r\npytz: 2017.3\r\nblosc: None\r\nbottleneck: None\r\ntables: None\r\nnumexpr: None\r\nfeather: None\r\nmatplotlib: 0+unknown\r\nopenpyxl: None\r\nxlrd: None\r\nxlwt: None\r\nxlsxwriter: None\r\nlxml: None\r\nbs4: None\r\nhtml5lib: None\r\nsqlalchemy: None\r\npymysql: None\r\npsycopg2: None\r\njinja2: None\r\ns3fs: None\r\nfastparquet: None\r\npandas_gbq: None\r\npandas_datareader: None\r\n```\r\n"
  },
  {
    "url": "https://api.github.com/repos/pandas-dev/pandas/issues/comments/345511038",
    "html_url": "https://github.com/pandas-dev/pandas/issues/18344#issuecomment-345511038",
    "issue_url": "https://api.github.com/repos/pandas-dev/pandas/issues/18344",
    "id": 345511038,
    "node_id": "MDEyOklzc3VlQ29tbWVudDM0NTUxMTAzOA==",
    "user": {
      "login": "TomAugspurger",
      "id": 1312546,
      "node_id": "MDQ6VXNlcjEzMTI1NDY=",
      "avatar_url": "https://avatars3.githubusercontent.com/u/1312546?v=4",
      "gravatar_id": "",
      "url": "https://api.github.com/users/TomAugspurger",
      "html_url": "https://github.com/TomAugspurger",
      "followers_url": "https://api.github.com/users/TomAugspurger/followers",
      "following_url": "https://api.github.com/users/TomAugspurger/following{/other_user}",
      "gists_url": "https://api.github.com/users/TomAugspurger/gists{/gist_id}",
      "starred_url": "https://api.github.com/users/TomAugspurger/starred{/owner}{/repo}",
      "subscriptions_url": "https://api.github.com/users/TomAugspurger/subscriptions",
      "organizations_url": "https://api.github.com/users/TomAugspurger/orgs",
      "repos_url": "https://api.github.com/users/TomAugspurger/repos",
      "events_url": "https://api.github.com/users/TomAugspurger/events{/privacy}",
      "received_events_url": "https://api.github.com/users/TomAugspurger/received_events",
      "type": "User",
      "site_admin": false
    },
    "created_at": "2017-11-19T11:57:48Z",
    "updated_at": "2017-11-19T11:57:48Z",
    "author_association": "CONTRIBUTOR",
    "body": "Is there a problem with the default formatter picked by pandas?\r\n\r\nYou're welcome to dig into `pandas/plotting/_converter.py` to see what's going on."
  },
  {
    "url": "https://api.github.com/repos/pandas-dev/pandas/issues/comments/345726899",
    "html_url": "https://github.com/pandas-dev/pandas/issues/18344#issuecomment-345726899",
    "issue_url": "https://api.github.com/repos/pandas-dev/pandas/issues/18344",
    "id": 345726899,
    "node_id": "MDEyOklzc3VlQ29tbWVudDM0NTcyNjg5OQ==",
    "user": {
      "login": "sakurai-youhei",
      "id": 721858,
      "node_id": "MDQ6VXNlcjcyMTg1OA==",
      "avatar_url": "https://avatars3.githubusercontent.com/u/721858?v=4",
      "gravatar_id": "",
      "url": "https://api.github.com/users/sakurai-youhei",
      "html_url": "https://github.com/sakurai-youhei",
      "followers_url": "https://api.github.com/users/sakurai-youhei/followers",
      "following_url": "https://api.github.com/users/sakurai-youhei/following{/other_user}",
      "gists_url": "https://api.github.com/users/sakurai-youhei/gists{/gist_id}",
      "starred_url": "https://api.github.com/users/sakurai-youhei/starred{/owner}{/repo}",
      "subscriptions_url": "https://api.github.com/users/sakurai-youhei/subscriptions",
      "organizations_url": "https://api.github.com/users/sakurai-youhei/orgs",
      "repos_url": "https://api.github.com/users/sakurai-youhei/repos",
      "events_url": "https://api.github.com/users/sakurai-youhei/events{/privacy}",
      "received_events_url": "https://api.github.com/users/sakurai-youhei/received_events",
      "type": "User",
      "site_admin": false
    },
    "created_at": "2017-11-20T15:19:33Z",
    "updated_at": "2017-11-20T15:19:33Z",
    "author_association": "NONE",
    "body": "@TomAugspurger Thanks for your guidance. Actually, problem was there's no relevant information in the Internet and problem for me right now is default locators look slightly different from AutoXxxLocator. :) If I'll have found root, I will suggest something here or through pull-request. Thanks."
  },
  {
    "url": "https://api.github.com/repos/pandas-dev/pandas/issues/comments/460646203",
    "html_url": "https://github.com/pandas-dev/pandas/issues/18344#issuecomment-460646203",
    "issue_url": "https://api.github.com/repos/pandas-dev/pandas/issues/18344",
    "id": 460646203,
    "node_id": "MDEyOklzc3VlQ29tbWVudDQ2MDY0NjIwMw==",
    "user": {
      "login": "joshmalina",
      "id": 5384924,
      "node_id": "MDQ6VXNlcjUzODQ5MjQ=",
      "avatar_url": "https://avatars0.githubusercontent.com/u/5384924?v=4",
      "gravatar_id": "",
      "url": "https://api.github.com/users/joshmalina",
      "html_url": "https://github.com/joshmalina",
      "followers_url": "https://api.github.com/users/joshmalina/followers",
      "following_url": "https://api.github.com/users/joshmalina/following{/other_user}",
      "gists_url": "https://api.github.com/users/joshmalina/gists{/gist_id}",
      "starred_url": "https://api.github.com/users/joshmalina/starred{/owner}{/repo}",
      "subscriptions_url": "https://api.github.com/users/joshmalina/subscriptions",
      "organizations_url": "https://api.github.com/users/joshmalina/orgs",
      "repos_url": "https://api.github.com/users/joshmalina/repos",
      "events_url": "https://api.github.com/users/joshmalina/events{/privacy}",
      "received_events_url": "https://api.github.com/users/joshmalina/received_events",
      "type": "User",
      "site_admin": false
    },
    "created_at": "2019-02-05T13:56:44Z",
    "updated_at": "2019-02-05T13:56:44Z",
    "author_association": "NONE",
    "body": "So this is not a fix, but if you call .to_timestamp() on the dataframe before you call plot, it converts it from a PeriodIndex to a DatetimeIndex, and then the issue is no longer there. It would be nice if this was fixed for PeriodIndex."
  }
]
