[
  {
    "url": "https://api.github.com/repos/pandas-dev/pandas/issues/comments/33447778",
    "html_url": "https://github.com/pandas-dev/pandas/pull/6111#issuecomment-33447778",
    "issue_url": "https://api.github.com/repos/pandas-dev/pandas/issues/6111",
    "id": 33447778,
    "node_id": "MDEyOklzc3VlQ29tbWVudDMzNDQ3Nzc4",
    "user": {
      "login": "ghost",
      "id": 10137,
      "node_id": "MDQ6VXNlcjEwMTM3",
      "avatar_url": "https://avatars3.githubusercontent.com/u/10137?v=4",
      "gravatar_id": "",
      "url": "https://api.github.com/users/ghost",
      "html_url": "https://github.com/ghost",
      "followers_url": "https://api.github.com/users/ghost/followers",
      "following_url": "https://api.github.com/users/ghost/following{/other_user}",
      "gists_url": "https://api.github.com/users/ghost/gists{/gist_id}",
      "starred_url": "https://api.github.com/users/ghost/starred{/owner}{/repo}",
      "subscriptions_url": "https://api.github.com/users/ghost/subscriptions",
      "organizations_url": "https://api.github.com/users/ghost/orgs",
      "repos_url": "https://api.github.com/users/ghost/repos",
      "events_url": "https://api.github.com/users/ghost/events{/privacy}",
      "received_events_url": "https://api.github.com/users/ghost/received_events",
      "type": "User",
      "site_admin": false
    },
    "created_at": "2014-01-28T03:13:53Z",
    "updated_at": "2014-01-28T03:14:45Z",
    "author_association": "NONE",
    "body": ":+1:. looks good.\n\nThe only issue is that we potentially have a box sitting on AWS's (travis) pipe \nflooding google.com with requests. But I can't see how that would actually happen.\nBombs away.\n"
  },
  {
    "url": "https://api.github.com/repos/pandas-dev/pandas/issues/comments/33477578",
    "html_url": "https://github.com/pandas-dev/pandas/pull/6111#issuecomment-33477578",
    "issue_url": "https://api.github.com/repos/pandas-dev/pandas/issues/6111",
    "id": 33477578,
    "node_id": "MDEyOklzc3VlQ29tbWVudDMzNDc3NTc4",
    "user": {
      "login": "jreback",
      "id": 953992,
      "node_id": "MDQ6VXNlcjk1Mzk5Mg==",
      "avatar_url": "https://avatars2.githubusercontent.com/u/953992?v=4",
      "gravatar_id": "",
      "url": "https://api.github.com/users/jreback",
      "html_url": "https://github.com/jreback",
      "followers_url": "https://api.github.com/users/jreback/followers",
      "following_url": "https://api.github.com/users/jreback/following{/other_user}",
      "gists_url": "https://api.github.com/users/jreback/gists{/gist_id}",
      "starred_url": "https://api.github.com/users/jreback/starred{/owner}{/repo}",
      "subscriptions_url": "https://api.github.com/users/jreback/subscriptions",
      "organizations_url": "https://api.github.com/users/jreback/orgs",
      "repos_url": "https://api.github.com/users/jreback/repos",
      "events_url": "https://api.github.com/users/jreback/events{/privacy}",
      "received_events_url": "https://api.github.com/users/jreback/received_events",
      "type": "User",
      "site_admin": false
    },
    "created_at": "2014-01-28T13:26:27Z",
    "updated_at": "2014-01-28T13:26:27Z",
    "author_association": "CONTRIBUTOR",
    "body": "Is this a legit error the network decorator should catch?\nhttp://scatterci.github.io/ScatterCI-Pandas/ on this commit: https://github.com/pydata/pandas/commit/54945de2\n\n```\n=============================================================================\nERROR: test_get_near_stock_price (pandas.io.tests.test_data.TestYahooOptions)\n-----------------------------------------------------------------------------\nTraceback (most recent call last):\n  File \"/usr/lib/python3.3/unittest/case.py\", line 384, in _executeTestPart\n    function()\n  File \"/home/travis/virtualenv/python3.3_with_system_site_packages/lib/python3.3/site-packages/pandas/util/testing.py\", line 1086, in wrapper\n    return t(*args, **kwargs)\n  File \"/home/travis/virtualenv/python3.3_with_system_site_packages/lib/python3.3/site-packages/pandas/io/tests/test_data.py\", line 279, in test_get_near_stock_price\n    expiry=self.expiry)\n  File \"/home/travis/virtualenv/python3.3_with_system_site_packages/lib/python3.3/site-packages/pandas/io/data.py\", line 781, in get_near_stock_price\n    price = float(get_quote_yahoo([self.symbol])['last'])\n  File \"/home/travis/virtualenv/python3.3_with_system_site_packages/lib/python3.3/site-packages/pandas/io/data.py\", line 132, in get_quote_yahoo\n    with urlopen(url_str) as url:\n  File \"/usr/lib/python3.3/urllib/request.py\", line 156, in urlopen\n    return opener.open(url, data, timeout)\n  File \"/usr/lib/python3.3/urllib/request.py\", line 475, in open\n    response = meth(req, response)\n  File \"/usr/lib/python3.3/urllib/request.py\", line 587, in http_response\n    'http', request, response, code, msg, hdrs)\n  File \"/usr/lib/python3.3/urllib/request.py\", line 507, in error\n    result = self._call_chain(*args)\n  File \"/usr/lib/python3.3/urllib/request.py\", line 447, in _call_chain\n    result = func(*args)\n  File \"/usr/lib/python3.3/urllib/request.py\", line 692, in http_error_302\n    return self.parent.open(new, timeout=req.timeout)\n  File \"/usr/lib/python3.3/urllib/request.py\", line 469, in open\n    response = self._open(req, data)\n  File \"/usr/lib/python3.3/urllib/request.py\", line 487, in _open\n    '_open', req)\n  File \"/usr/lib/python3.3/urllib/request.py\", line 447, in _call_chain\n    result = func(*args)\n  File \"/usr/lib/python3.3/urllib/request.py\", line 1268, in http_open\n    return self.do_open(http.client.HTTPConnection, req)\n  File \"/usr/lib/python3.3/urllib/request.py\", line 1253, in do_open\n    r = h.getresponse()\n  File \"/usr/lib/python3.3/http/client.py\", line 1147, in getresponse\n    response.begin()\n  File \"/usr/lib/python3.3/http/client.py\", line 358, in begin\n    version, status, reason = self._read_status()\n  File \"/usr/lib/python3.3/http/client.py\", line 320, in _read_status\n    line = str(self.fp.readline(_MAXLINE + 1), \"iso-8859-1\")\n  File \"/usr/lib/python3.3/socket.py\", line 297, in readinto\n    return self._sock.recv_into(b)\nConnectionResetError: [Errno 104] Connection reset by peer\n```\n"
  },
  {
    "url": "https://api.github.com/repos/pandas-dev/pandas/issues/comments/33558733",
    "html_url": "https://github.com/pandas-dev/pandas/pull/6111#issuecomment-33558733",
    "issue_url": "https://api.github.com/repos/pandas-dev/pandas/issues/6111",
    "id": 33558733,
    "node_id": "MDEyOklzc3VlQ29tbWVudDMzNTU4NzMz",
    "user": {
      "login": "jtratner",
      "id": 1598379,
      "node_id": "MDQ6VXNlcjE1OTgzNzk=",
      "avatar_url": "https://avatars1.githubusercontent.com/u/1598379?v=4",
      "gravatar_id": "",
      "url": "https://api.github.com/users/jtratner",
      "html_url": "https://github.com/jtratner",
      "followers_url": "https://api.github.com/users/jtratner/followers",
      "following_url": "https://api.github.com/users/jtratner/following{/other_user}",
      "gists_url": "https://api.github.com/users/jtratner/gists{/gist_id}",
      "starred_url": "https://api.github.com/users/jtratner/starred{/owner}{/repo}",
      "subscriptions_url": "https://api.github.com/users/jtratner/subscriptions",
      "organizations_url": "https://api.github.com/users/jtratner/orgs",
      "repos_url": "https://api.github.com/users/jtratner/repos",
      "events_url": "https://api.github.com/users/jtratner/events{/privacy}",
      "received_events_url": "https://api.github.com/users/jtratner/received_events",
      "type": "User",
      "site_admin": false
    },
    "created_at": "2014-01-29T05:56:36Z",
    "updated_at": "2014-01-29T05:56:36Z",
    "author_association": "CONTRIBUTOR",
    "body": "Probably, but I recall issues with all the different error types for\nsockets and other IO errors. @cpcloud - you have any recollection where\nthis ended up?\nOn Jan 28, 2014 5:26 AM, \"jreback\" notifications@github.com wrote:\n\nIs this a legit error the network decorator should catch?\nhttp://scatterci.github.io/ScatterCI-Pandas/ on this commit:\n54945dehttps://github.com/pydata/pandas/commit/54945de2\n\n# \n\n## ERROR: test_get_near_stock_price (pandas.io.tests.test_data.TestYahooOptions)\n\nTraceback (most recent call last):\n  File \"/usr/lib/python3.3/unittest/case.py\", line 384, in _executeTestPart\n    function()\n  File \"/home/travis/virtualenv/python3.3_with_system_site_packages/lib/python3.3/site-packages/pandas/util/testing.py\",\nline 1086, in wrapper\n    return t(_args, *_kwargs)\n  File \"/home/travis/virtualenv/python3.3_with_system_site_packages/lib/python3.3/site-packages/pandas/io/tests/test_data.py\",\nline 279, in test_get_near_stock_price\n    expiry=self.expiry)\n  File \"/home/travis/virtualenv/python3.3_with_system_site_packages/lib/python3.3/site-packages/pandas/io/data.py\",\nline 781, in get_near_stock_price\n    price = float(get_quote_yahoo([self.symbol])['last'])\n  File \"/home/travis/virtualenv/python3.3_with_system_site_packages/lib/python3.3/site-packages/pandas/io/data.py\",\nline 132, in get_quote_yahoo\n    with urlopen(url_str) as url:\n  File \"/usr/lib/python3.3/urllib/request.py\", line 156, in urlopen\n    return opener.open(url, data, timeout)\n  File \"/usr/lib/python3.3/urllib/request.py\", line 475, in open\n    response = meth(req, response)\n  File \"/usr/lib/python3.3/urllib/request.py\", line 587, in http_response\n    'http', request, response, code, msg, hdrs)\n  File \"/usr/lib/python3.3/urllib/request.py\", line 507, in error\n    result = self._call_chain(_args)\n  File \"/usr/lib/python3.3/urllib/request.py\", line 447, in _call_chain\n    result = func(_args)\n  File \"/usr/lib/python3.3/urllib/request.py\", line 692, in http_error_302\n    return self.parent.open(new, timeout=req.timeout)\n  File \"/usr/lib/python3.3/urllib/request.py\", line 469, in open\n    response = self._open(req, data)\n  File \"/usr/lib/python3.3/urllib/request.py\", line 487, in _open\n    '_open', req)\n  File \"/usr/lib/python3.3/urllib/request.py\", line 447, in _call_chain\n    result = func(*args)\n  File \"/usr/lib/python3.3/urllib/request.py\", line 1268, in http_open\n    return self.do_open(http.client.HTTPConnection, req)\n  File \"/usr/lib/python3.3/urllib/request.py\", line 1253, in do_open\n    r = h.getresponse()\n  File \"/usr/lib/python3.3/http/client.py\", line 1147, in getresponse\n    response.begin()\n  File \"/usr/lib/python3.3/http/client.py\", line 358, in begin\n    version, status, reason = self._read_status()\n  File \"/usr/lib/python3.3/http/client.py\", line 320, in _read_status\n    line = str(self.fp.readline(_MAXLINE + 1), \"iso-8859-1\")\n  File \"/usr/lib/python3.3/socket.py\", line 297, in readinto\n    return self._sock.recv_into(b)\nConnectionResetError: [Errno 104] Connection reset by peer\n\n## \n\nReply to this email directly or view it on\nGitHubhttps://github.com/pydata/pandas/pull/6111#issuecomment-33477578\n.\n"
  }
]
