[
  {
    "url": "https://api.github.com/repos/ipython/ipython/issues/comments/324315133",
    "html_url": "https://github.com/ipython/ipython/issues/10753#issuecomment-324315133",
    "issue_url": "https://api.github.com/repos/ipython/ipython/issues/10753",
    "id": 324315133,
    "node_id": "MDEyOklzc3VlQ29tbWVudDMyNDMxNTEzMw==",
    "user": {
      "login": "takluyver",
      "id": 327925,
      "node_id": "MDQ6VXNlcjMyNzkyNQ==",
      "avatar_url": "https://avatars3.githubusercontent.com/u/327925?v=4",
      "gravatar_id": "",
      "url": "https://api.github.com/users/takluyver",
      "html_url": "https://github.com/takluyver",
      "followers_url": "https://api.github.com/users/takluyver/followers",
      "following_url": "https://api.github.com/users/takluyver/following{/other_user}",
      "gists_url": "https://api.github.com/users/takluyver/gists{/gist_id}",
      "starred_url": "https://api.github.com/users/takluyver/starred{/owner}{/repo}",
      "subscriptions_url": "https://api.github.com/users/takluyver/subscriptions",
      "organizations_url": "https://api.github.com/users/takluyver/orgs",
      "repos_url": "https://api.github.com/users/takluyver/repos",
      "events_url": "https://api.github.com/users/takluyver/events{/privacy}",
      "received_events_url": "https://api.github.com/users/takluyver/received_events",
      "type": "User",
      "site_admin": false
    },
    "created_at": "2017-08-23T12:34:51Z",
    "updated_at": "2017-08-23T12:34:51Z",
    "author_association": "MEMBER",
    "body": "The error handling is meant to move the file aside and create a new one. I would guess there's a race condition in that - if two processes try to move it aside at almost the same time, one of them fails.\r\n\r\nI don't know why it's going wrong in the first place, but if there are enough processes competing to write to the history database, it's possible that one of them ends up waiting more than the default 5 second timeout, at which point it will raise the first error you show."
  },
  {
    "url": "https://api.github.com/repos/ipython/ipython/issues/comments/324325540",
    "html_url": "https://github.com/ipython/ipython/issues/10753#issuecomment-324325540",
    "issue_url": "https://api.github.com/repos/ipython/ipython/issues/10753",
    "id": 324325540,
    "node_id": "MDEyOklzc3VlQ29tbWVudDMyNDMyNTU0MA==",
    "user": {
      "login": "abukaj",
      "id": 11304359,
      "node_id": "MDQ6VXNlcjExMzA0MzU5",
      "avatar_url": "https://avatars1.githubusercontent.com/u/11304359?v=4",
      "gravatar_id": "",
      "url": "https://api.github.com/users/abukaj",
      "html_url": "https://github.com/abukaj",
      "followers_url": "https://api.github.com/users/abukaj/followers",
      "following_url": "https://api.github.com/users/abukaj/following{/other_user}",
      "gists_url": "https://api.github.com/users/abukaj/gists{/gist_id}",
      "starred_url": "https://api.github.com/users/abukaj/starred{/owner}{/repo}",
      "subscriptions_url": "https://api.github.com/users/abukaj/subscriptions",
      "organizations_url": "https://api.github.com/users/abukaj/orgs",
      "repos_url": "https://api.github.com/users/abukaj/repos",
      "events_url": "https://api.github.com/users/abukaj/events{/privacy}",
      "received_events_url": "https://api.github.com/users/abukaj/received_events",
      "type": "User",
      "site_admin": false
    },
    "created_at": "2017-08-23T13:10:44Z",
    "updated_at": "2017-08-23T13:10:44Z",
    "author_association": "NONE",
    "body": "@takluyver Is it possible to disable writing to the history database by a kernel?\r\nIt would fix the issue for me."
  },
  {
    "url": "https://api.github.com/repos/ipython/ipython/issues/comments/324344151",
    "html_url": "https://github.com/ipython/ipython/issues/10753#issuecomment-324344151",
    "issue_url": "https://api.github.com/repos/ipython/ipython/issues/10753",
    "id": 324344151,
    "node_id": "MDEyOklzc3VlQ29tbWVudDMyNDM0NDE1MQ==",
    "user": {
      "login": "takluyver",
      "id": 327925,
      "node_id": "MDQ6VXNlcjMyNzkyNQ==",
      "avatar_url": "https://avatars3.githubusercontent.com/u/327925?v=4",
      "gravatar_id": "",
      "url": "https://api.github.com/users/takluyver",
      "html_url": "https://github.com/takluyver",
      "followers_url": "https://api.github.com/users/takluyver/followers",
      "following_url": "https://api.github.com/users/takluyver/following{/other_user}",
      "gists_url": "https://api.github.com/users/takluyver/gists{/gist_id}",
      "starred_url": "https://api.github.com/users/takluyver/starred{/owner}{/repo}",
      "subscriptions_url": "https://api.github.com/users/takluyver/subscriptions",
      "organizations_url": "https://api.github.com/users/takluyver/orgs",
      "repos_url": "https://api.github.com/users/takluyver/repos",
      "events_url": "https://api.github.com/users/takluyver/events{/privacy}",
      "received_events_url": "https://api.github.com/users/takluyver/received_events",
      "type": "User",
      "site_admin": false
    },
    "created_at": "2017-08-23T14:07:45Z",
    "updated_at": "2017-08-23T14:07:45Z",
    "author_association": "MEMBER",
    "body": "Yup, the config option is called `HistoryAccessor.enabled`\r\n\r\nhttp://ipython.readthedocs.io/en/latest/config/options/terminal.html#configtrait-HistoryAccessor.enabled"
  }
]
