[
  {
    "url": "https://api.github.com/repos/ipython/ipython/issues/comments/420068690",
    "html_url": "https://github.com/ipython/ipython/issues/11057#issuecomment-420068690",
    "issue_url": "https://api.github.com/repos/ipython/ipython/issues/11057",
    "id": 420068690,
    "node_id": "MDEyOklzc3VlQ29tbWVudDQyMDA2ODY5MA==",
    "user": {
      "login": "teeberg",
      "id": 199071,
      "node_id": "MDQ6VXNlcjE5OTA3MQ==",
      "avatar_url": "https://avatars1.githubusercontent.com/u/199071?v=4",
      "gravatar_id": "",
      "url": "https://api.github.com/users/teeberg",
      "html_url": "https://github.com/teeberg",
      "followers_url": "https://api.github.com/users/teeberg/followers",
      "following_url": "https://api.github.com/users/teeberg/following{/other_user}",
      "gists_url": "https://api.github.com/users/teeberg/gists{/gist_id}",
      "starred_url": "https://api.github.com/users/teeberg/starred{/owner}{/repo}",
      "subscriptions_url": "https://api.github.com/users/teeberg/subscriptions",
      "organizations_url": "https://api.github.com/users/teeberg/orgs",
      "repos_url": "https://api.github.com/users/teeberg/repos",
      "events_url": "https://api.github.com/users/teeberg/events{/privacy}",
      "received_events_url": "https://api.github.com/users/teeberg/received_events",
      "type": "User",
      "site_admin": false
    },
    "created_at": "2018-09-10T21:33:14Z",
    "updated_at": "2018-09-10T21:33:14Z",
    "author_association": "NONE",
    "body": "I'm also having this problem and am currently googling around and crawling through this repo's issues. Looks like this has also been reported in https://github.com/ipython/ipython/issues/9978"
  },
  {
    "url": "https://api.github.com/repos/ipython/ipython/issues/comments/420086397",
    "html_url": "https://github.com/ipython/ipython/issues/11057#issuecomment-420086397",
    "issue_url": "https://api.github.com/repos/ipython/ipython/issues/11057",
    "id": 420086397,
    "node_id": "MDEyOklzc3VlQ29tbWVudDQyMDA4NjM5Nw==",
    "user": {
      "login": "Tahnan",
      "id": 1123113,
      "node_id": "MDQ6VXNlcjExMjMxMTM=",
      "avatar_url": "https://avatars1.githubusercontent.com/u/1123113?v=4",
      "gravatar_id": "",
      "url": "https://api.github.com/users/Tahnan",
      "html_url": "https://github.com/Tahnan",
      "followers_url": "https://api.github.com/users/Tahnan/followers",
      "following_url": "https://api.github.com/users/Tahnan/following{/other_user}",
      "gists_url": "https://api.github.com/users/Tahnan/gists{/gist_id}",
      "starred_url": "https://api.github.com/users/Tahnan/starred{/owner}{/repo}",
      "subscriptions_url": "https://api.github.com/users/Tahnan/subscriptions",
      "organizations_url": "https://api.github.com/users/Tahnan/orgs",
      "repos_url": "https://api.github.com/users/Tahnan/repos",
      "events_url": "https://api.github.com/users/Tahnan/events{/privacy}",
      "received_events_url": "https://api.github.com/users/Tahnan/received_events",
      "type": "User",
      "site_admin": false
    },
    "created_at": "2018-09-10T22:47:31Z",
    "updated_at": "2018-09-10T22:47:31Z",
    "author_association": "NONE",
    "body": "Aha!  Thank you for seeing that other report--as I said, I did try to search, but it's *really hard* to search for bugs with %run."
  },
  {
    "url": "https://api.github.com/repos/ipython/ipython/issues/comments/420329350",
    "html_url": "https://github.com/ipython/ipython/issues/11057#issuecomment-420329350",
    "issue_url": "https://api.github.com/repos/ipython/ipython/issues/11057",
    "id": 420329350,
    "node_id": "MDEyOklzc3VlQ29tbWVudDQyMDMyOTM1MA==",
    "user": {
      "login": "Carreau",
      "id": 335567,
      "node_id": "MDQ6VXNlcjMzNTU2Nw==",
      "avatar_url": "https://avatars3.githubusercontent.com/u/335567?v=4",
      "gravatar_id": "",
      "url": "https://api.github.com/users/Carreau",
      "html_url": "https://github.com/Carreau",
      "followers_url": "https://api.github.com/users/Carreau/followers",
      "following_url": "https://api.github.com/users/Carreau/following{/other_user}",
      "gists_url": "https://api.github.com/users/Carreau/gists{/gist_id}",
      "starred_url": "https://api.github.com/users/Carreau/starred{/owner}{/repo}",
      "subscriptions_url": "https://api.github.com/users/Carreau/subscriptions",
      "organizations_url": "https://api.github.com/users/Carreau/orgs",
      "repos_url": "https://api.github.com/users/Carreau/repos",
      "events_url": "https://api.github.com/users/Carreau/events{/privacy}",
      "received_events_url": "https://api.github.com/users/Carreau/received_events",
      "type": "User",
      "site_admin": false
    },
    "created_at": "2018-09-11T16:10:49Z",
    "updated_at": "2018-09-11T16:10:49Z",
    "author_association": "MEMBER",
    "body": "That seem to be a bug in Python itself. On more recent version of Python, this does not appear to crash for me. As said in linked issue:\r\n\r\n> From the traceback, it looks like it might even be an issue with Python's own inspect library, which assumes that modules have a __name__ attribute. We do already go to some lengths to work around inspect issues, but I'd rather not pile on more monkeypatches.\r\n\r\nClosing as duplicated."
  }
]
