[
  {
    "url": "https://api.github.com/repos/ipython/ipython/issues/comments/6512701",
    "html_url": "https://github.com/ipython/ipython/issues/2005#issuecomment-6512701",
    "issue_url": "https://api.github.com/repos/ipython/ipython/issues/2005",
    "id": 6512701,
    "node_id": "MDEyOklzc3VlQ29tbWVudDY1MTI3MDE=",
    "user": {
      "login": "Carreau",
      "id": 335567,
      "node_id": "MDQ6VXNlcjMzNTU2Nw==",
      "avatar_url": "https://avatars3.githubusercontent.com/u/335567?v=4",
      "gravatar_id": "",
      "url": "https://api.github.com/users/Carreau",
      "html_url": "https://github.com/Carreau",
      "followers_url": "https://api.github.com/users/Carreau/followers",
      "following_url": "https://api.github.com/users/Carreau/following{/other_user}",
      "gists_url": "https://api.github.com/users/Carreau/gists{/gist_id}",
      "starred_url": "https://api.github.com/users/Carreau/starred{/owner}{/repo}",
      "subscriptions_url": "https://api.github.com/users/Carreau/subscriptions",
      "organizations_url": "https://api.github.com/users/Carreau/orgs",
      "repos_url": "https://api.github.com/users/Carreau/repos",
      "events_url": "https://api.github.com/users/Carreau/events{/privacy}",
      "received_events_url": "https://api.github.com/users/Carreau/received_events",
      "type": "User",
      "site_admin": false
    },
    "created_at": "2012-06-22T16:54:48Z",
    "updated_at": "2012-06-22T16:54:48Z",
    "author_association": "MEMBER",
    "body": "Related to the comment i posted on #1883 i think. Used to test the font height to get around a bug.\n"
  },
  {
    "url": "https://api.github.com/repos/ipython/ipython/issues/comments/6513878",
    "html_url": "https://github.com/ipython/ipython/issues/2005#issuecomment-6513878",
    "issue_url": "https://api.github.com/repos/ipython/ipython/issues/2005",
    "id": 6513878,
    "node_id": "MDEyOklzc3VlQ29tbWVudDY1MTM4Nzg=",
    "user": {
      "login": "ellisonbg",
      "id": 27600,
      "node_id": "MDQ6VXNlcjI3NjAw",
      "avatar_url": "https://avatars3.githubusercontent.com/u/27600?v=4",
      "gravatar_id": "",
      "url": "https://api.github.com/users/ellisonbg",
      "html_url": "https://github.com/ellisonbg",
      "followers_url": "https://api.github.com/users/ellisonbg/followers",
      "following_url": "https://api.github.com/users/ellisonbg/following{/other_user}",
      "gists_url": "https://api.github.com/users/ellisonbg/gists{/gist_id}",
      "starred_url": "https://api.github.com/users/ellisonbg/starred{/owner}{/repo}",
      "subscriptions_url": "https://api.github.com/users/ellisonbg/subscriptions",
      "organizations_url": "https://api.github.com/users/ellisonbg/orgs",
      "repos_url": "https://api.github.com/users/ellisonbg/repos",
      "events_url": "https://api.github.com/users/ellisonbg/events{/privacy}",
      "received_events_url": "https://api.github.com/users/ellisonbg/received_events",
      "type": "User",
      "site_admin": false
    },
    "created_at": "2012-06-22T17:43:13Z",
    "updated_at": "2012-06-22T17:43:13Z",
    "author_association": "MEMBER",
    "body": "Hmm, that is the pager area, and it looks like there is a payload of\nsome sort showing up.  This area is written to when you do things like\n\"foo?\".\n\nOn Fri, Jun 22, 2012 at 7:53 AM, Chris Fonnesbeck\nreply@reply.github.com\nwrote:\n\n> Occasionally, I will notice an odd footer appear at the bottom of an iPython notebook with what appears to be a series of x's:\n> \n> http://cl.ly/1E1V0P03342v341j0w12\n> \n> Any idea what this is? It has happened in a couple of very different notebook projects. Running 0.13.dev on Python 2.7.1 (OS X 10.7.4).\n> \n> ---\n> \n> Reply to this email directly or view it on GitHub:\n> https://github.com/ipython/ipython/issues/2005\n\n## \n\nBrian E. Granger\nCal Poly State University, San Luis Obispo\nbgranger@calpoly.edu and ellisonbg@gmail.com\n"
  },
  {
    "url": "https://api.github.com/repos/ipython/ipython/issues/comments/6514324",
    "html_url": "https://github.com/ipython/ipython/issues/2005#issuecomment-6514324",
    "issue_url": "https://api.github.com/repos/ipython/ipython/issues/2005",
    "id": 6514324,
    "node_id": "MDEyOklzc3VlQ29tbWVudDY1MTQzMjQ=",
    "user": {
      "login": "fonnesbeck",
      "id": 81476,
      "node_id": "MDQ6VXNlcjgxNDc2",
      "avatar_url": "https://avatars3.githubusercontent.com/u/81476?v=4",
      "gravatar_id": "",
      "url": "https://api.github.com/users/fonnesbeck",
      "html_url": "https://github.com/fonnesbeck",
      "followers_url": "https://api.github.com/users/fonnesbeck/followers",
      "following_url": "https://api.github.com/users/fonnesbeck/following{/other_user}",
      "gists_url": "https://api.github.com/users/fonnesbeck/gists{/gist_id}",
      "starred_url": "https://api.github.com/users/fonnesbeck/starred{/owner}{/repo}",
      "subscriptions_url": "https://api.github.com/users/fonnesbeck/subscriptions",
      "organizations_url": "https://api.github.com/users/fonnesbeck/orgs",
      "repos_url": "https://api.github.com/users/fonnesbeck/repos",
      "events_url": "https://api.github.com/users/fonnesbeck/events{/privacy}",
      "received_events_url": "https://api.github.com/users/fonnesbeck/received_events",
      "type": "User",
      "site_admin": false
    },
    "created_at": "2012-06-22T18:02:04Z",
    "updated_at": "2012-06-22T18:02:04Z",
    "author_association": "NONE",
    "body": "No, just any error does not generate it. The problem is that its so subtle that I don't notice it right away, so I have not been able to pinpoint when it happens. However, running all the cells of a working notebook does not trigger it, so it appears to be related to an exception somehow. I will try keeping a closer eye on it.\n"
  },
  {
    "url": "https://api.github.com/repos/ipython/ipython/issues/comments/6520071",
    "html_url": "https://github.com/ipython/ipython/issues/2005#issuecomment-6520071",
    "issue_url": "https://api.github.com/repos/ipython/ipython/issues/2005",
    "id": 6520071,
    "node_id": "MDEyOklzc3VlQ29tbWVudDY1MjAwNzE=",
    "user": {
      "login": "fperez",
      "id": 57394,
      "node_id": "MDQ6VXNlcjU3Mzk0",
      "avatar_url": "https://avatars1.githubusercontent.com/u/57394?v=4",
      "gravatar_id": "",
      "url": "https://api.github.com/users/fperez",
      "html_url": "https://github.com/fperez",
      "followers_url": "https://api.github.com/users/fperez/followers",
      "following_url": "https://api.github.com/users/fperez/following{/other_user}",
      "gists_url": "https://api.github.com/users/fperez/gists{/gist_id}",
      "starred_url": "https://api.github.com/users/fperez/starred{/owner}{/repo}",
      "subscriptions_url": "https://api.github.com/users/fperez/subscriptions",
      "organizations_url": "https://api.github.com/users/fperez/orgs",
      "repos_url": "https://api.github.com/users/fperez/repos",
      "events_url": "https://api.github.com/users/fperez/events{/privacy}",
      "received_events_url": "https://api.github.com/users/fperez/received_events",
      "type": "User",
      "site_admin": false
    },
    "created_at": "2012-06-22T22:49:35Z",
    "updated_at": "2012-06-22T22:49:35Z",
    "author_association": "MEMBER",
    "body": "@mcelrath, it looks like that Courier New bug is going to haunt us forever... I haven't seen this problem yet, but we should do something about it before the release.  Argh...\n"
  },
  {
    "url": "https://api.github.com/repos/ipython/ipython/issues/comments/6522502",
    "html_url": "https://github.com/ipython/ipython/issues/2005#issuecomment-6522502",
    "issue_url": "https://api.github.com/repos/ipython/ipython/issues/2005",
    "id": 6522502,
    "node_id": "MDEyOklzc3VlQ29tbWVudDY1MjI1MDI=",
    "user": {
      "login": "mcelrath",
      "id": 1746780,
      "node_id": "MDQ6VXNlcjE3NDY3ODA=",
      "avatar_url": "https://avatars2.githubusercontent.com/u/1746780?v=4",
      "gravatar_id": "",
      "url": "https://api.github.com/users/mcelrath",
      "html_url": "https://github.com/mcelrath",
      "followers_url": "https://api.github.com/users/mcelrath/followers",
      "following_url": "https://api.github.com/users/mcelrath/following{/other_user}",
      "gists_url": "https://api.github.com/users/mcelrath/gists{/gist_id}",
      "starred_url": "https://api.github.com/users/mcelrath/starred{/owner}{/repo}",
      "subscriptions_url": "https://api.github.com/users/mcelrath/subscriptions",
      "organizations_url": "https://api.github.com/users/mcelrath/orgs",
      "repos_url": "https://api.github.com/users/mcelrath/repos",
      "events_url": "https://api.github.com/users/mcelrath/events{/privacy}",
      "received_events_url": "https://api.github.com/users/mcelrath/received_events",
      "type": "User",
      "site_admin": false
    },
    "created_at": "2012-06-23T04:27:59Z",
    "updated_at": "2012-06-23T04:27:59Z",
    "author_association": "NONE",
    "body": "Nah it's a minor problem, please pull #2012 to fix it.\n"
  },
  {
    "url": "https://api.github.com/repos/ipython/ipython/issues/comments/6522838",
    "html_url": "https://github.com/ipython/ipython/issues/2005#issuecomment-6522838",
    "issue_url": "https://api.github.com/repos/ipython/ipython/issues/2005",
    "id": 6522838,
    "node_id": "MDEyOklzc3VlQ29tbWVudDY1MjI4Mzg=",
    "user": {
      "login": "fperez",
      "id": 57394,
      "node_id": "MDQ6VXNlcjU3Mzk0",
      "avatar_url": "https://avatars1.githubusercontent.com/u/57394?v=4",
      "gravatar_id": "",
      "url": "https://api.github.com/users/fperez",
      "html_url": "https://github.com/fperez",
      "followers_url": "https://api.github.com/users/fperez/followers",
      "following_url": "https://api.github.com/users/fperez/following{/other_user}",
      "gists_url": "https://api.github.com/users/fperez/gists{/gist_id}",
      "starred_url": "https://api.github.com/users/fperez/starred{/owner}{/repo}",
      "subscriptions_url": "https://api.github.com/users/fperez/subscriptions",
      "organizations_url": "https://api.github.com/users/fperez/orgs",
      "repos_url": "https://api.github.com/users/fperez/repos",
      "events_url": "https://api.github.com/users/fperez/events{/privacy}",
      "received_events_url": "https://api.github.com/users/fperez/received_events",
      "type": "User",
      "site_admin": false
    },
    "created_at": "2012-06-23T05:50:44Z",
    "updated_at": "2012-06-23T05:50:44Z",
    "author_association": "MEMBER",
    "body": "Great, thanks!  Will have a look now...\n"
  },
  {
    "url": "https://api.github.com/repos/ipython/ipython/issues/comments/6522854",
    "html_url": "https://github.com/ipython/ipython/issues/2005#issuecomment-6522854",
    "issue_url": "https://api.github.com/repos/ipython/ipython/issues/2005",
    "id": 6522854,
    "node_id": "MDEyOklzc3VlQ29tbWVudDY1MjI4NTQ=",
    "user": {
      "login": "fperez",
      "id": 57394,
      "node_id": "MDQ6VXNlcjU3Mzk0",
      "avatar_url": "https://avatars1.githubusercontent.com/u/57394?v=4",
      "gravatar_id": "",
      "url": "https://api.github.com/users/fperez",
      "html_url": "https://github.com/fperez",
      "followers_url": "https://api.github.com/users/fperez/followers",
      "following_url": "https://api.github.com/users/fperez/following{/other_user}",
      "gists_url": "https://api.github.com/users/fperez/gists{/gist_id}",
      "starred_url": "https://api.github.com/users/fperez/starred{/owner}{/repo}",
      "subscriptions_url": "https://api.github.com/users/fperez/subscriptions",
      "organizations_url": "https://api.github.com/users/fperez/orgs",
      "repos_url": "https://api.github.com/users/fperez/repos",
      "events_url": "https://api.github.com/users/fperez/events{/privacy}",
      "received_events_url": "https://api.github.com/users/fperez/received_events",
      "type": "User",
      "site_admin": false
    },
    "created_at": "2012-06-23T05:55:45Z",
    "updated_at": "2012-06-23T05:55:45Z",
    "author_association": "MEMBER",
    "body": "@fonnesbeck, please let us know if the merge of #2012 fixes everything.  I reviewed it and the code looked clean, but since the problem doesn't seem to be easy to trigger, I prefer to merge now so we have more testing in the wild.\n"
  },
  {
    "url": "https://api.github.com/repos/ipython/ipython/issues/comments/6528728",
    "html_url": "https://github.com/ipython/ipython/issues/2005#issuecomment-6528728",
    "issue_url": "https://api.github.com/repos/ipython/ipython/issues/2005",
    "id": 6528728,
    "node_id": "MDEyOklzc3VlQ29tbWVudDY1Mjg3Mjg=",
    "user": {
      "login": "fonnesbeck",
      "id": 81476,
      "node_id": "MDQ6VXNlcjgxNDc2",
      "avatar_url": "https://avatars3.githubusercontent.com/u/81476?v=4",
      "gravatar_id": "",
      "url": "https://api.github.com/users/fonnesbeck",
      "html_url": "https://github.com/fonnesbeck",
      "followers_url": "https://api.github.com/users/fonnesbeck/followers",
      "following_url": "https://api.github.com/users/fonnesbeck/following{/other_user}",
      "gists_url": "https://api.github.com/users/fonnesbeck/gists{/gist_id}",
      "starred_url": "https://api.github.com/users/fonnesbeck/starred{/owner}{/repo}",
      "subscriptions_url": "https://api.github.com/users/fonnesbeck/subscriptions",
      "organizations_url": "https://api.github.com/users/fonnesbeck/orgs",
      "repos_url": "https://api.github.com/users/fonnesbeck/repos",
      "events_url": "https://api.github.com/users/fonnesbeck/events{/privacy}",
      "received_events_url": "https://api.github.com/users/fonnesbeck/received_events",
      "type": "User",
      "site_admin": false
    },
    "created_at": "2012-06-23T22:05:24Z",
    "updated_at": "2012-06-23T22:05:24Z",
    "author_association": "NONE",
    "body": "I've just pulled the fix, so I will let you know if I see it again. Thanks for the fast action.\n"
  }
]
