[
  {
    "url": "https://api.github.com/repos/ipython/ipython/issues/comments/76988699",
    "html_url": "https://github.com/ipython/ipython/issues/7947#issuecomment-76988699",
    "issue_url": "https://api.github.com/repos/ipython/ipython/issues/7947",
    "id": 76988699,
    "node_id": "MDEyOklzc3VlQ29tbWVudDc2OTg4Njk5",
    "user": {
      "login": "takluyver",
      "id": 327925,
      "node_id": "MDQ6VXNlcjMyNzkyNQ==",
      "avatar_url": "https://avatars3.githubusercontent.com/u/327925?v=4",
      "gravatar_id": "",
      "url": "https://api.github.com/users/takluyver",
      "html_url": "https://github.com/takluyver",
      "followers_url": "https://api.github.com/users/takluyver/followers",
      "following_url": "https://api.github.com/users/takluyver/following{/other_user}",
      "gists_url": "https://api.github.com/users/takluyver/gists{/gist_id}",
      "starred_url": "https://api.github.com/users/takluyver/starred{/owner}{/repo}",
      "subscriptions_url": "https://api.github.com/users/takluyver/subscriptions",
      "organizations_url": "https://api.github.com/users/takluyver/orgs",
      "repos_url": "https://api.github.com/users/takluyver/repos",
      "events_url": "https://api.github.com/users/takluyver/events{/privacy}",
      "received_events_url": "https://api.github.com/users/takluyver/received_events",
      "type": "User",
      "site_admin": false
    },
    "created_at": "2015-03-03T17:11:46Z",
    "updated_at": "2015-03-03T17:11:46Z",
    "author_association": "MEMBER",
    "body": "I think that means Python is failing to find its own standard library. I'm not sure why that would happen, though.\n"
  },
  {
    "url": "https://api.github.com/repos/ipython/ipython/issues/comments/76996933",
    "html_url": "https://github.com/ipython/ipython/issues/7947#issuecomment-76996933",
    "issue_url": "https://api.github.com/repos/ipython/ipython/issues/7947",
    "id": 76996933,
    "node_id": "MDEyOklzc3VlQ29tbWVudDc2OTk2OTMz",
    "user": {
      "login": "cel4",
      "id": 3819470,
      "node_id": "MDQ6VXNlcjM4MTk0NzA=",
      "avatar_url": "https://avatars1.githubusercontent.com/u/3819470?v=4",
      "gravatar_id": "",
      "url": "https://api.github.com/users/cel4",
      "html_url": "https://github.com/cel4",
      "followers_url": "https://api.github.com/users/cel4/followers",
      "following_url": "https://api.github.com/users/cel4/following{/other_user}",
      "gists_url": "https://api.github.com/users/cel4/gists{/gist_id}",
      "starred_url": "https://api.github.com/users/cel4/starred{/owner}{/repo}",
      "subscriptions_url": "https://api.github.com/users/cel4/subscriptions",
      "organizations_url": "https://api.github.com/users/cel4/orgs",
      "repos_url": "https://api.github.com/users/cel4/repos",
      "events_url": "https://api.github.com/users/cel4/events{/privacy}",
      "received_events_url": "https://api.github.com/users/cel4/received_events",
      "type": "User",
      "site_admin": false
    },
    "created_at": "2015-03-03T17:51:17Z",
    "updated_at": "2015-03-03T17:51:17Z",
    "author_association": "CONTRIBUTOR",
    "body": "For me it does not work for any python interpreter in a virtualenv. Is this reproducible or is it just me?\n"
  },
  {
    "url": "https://api.github.com/repos/ipython/ipython/issues/comments/76997665",
    "html_url": "https://github.com/ipython/ipython/issues/7947#issuecomment-76997665",
    "issue_url": "https://api.github.com/repos/ipython/ipython/issues/7947",
    "id": 76997665,
    "node_id": "MDEyOklzc3VlQ29tbWVudDc2OTk3NjY1",
    "user": {
      "login": "takluyver",
      "id": 327925,
      "node_id": "MDQ6VXNlcjMyNzkyNQ==",
      "avatar_url": "https://avatars3.githubusercontent.com/u/327925?v=4",
      "gravatar_id": "",
      "url": "https://api.github.com/users/takluyver",
      "html_url": "https://github.com/takluyver",
      "followers_url": "https://api.github.com/users/takluyver/followers",
      "following_url": "https://api.github.com/users/takluyver/following{/other_user}",
      "gists_url": "https://api.github.com/users/takluyver/gists{/gist_id}",
      "starred_url": "https://api.github.com/users/takluyver/starred{/owner}{/repo}",
      "subscriptions_url": "https://api.github.com/users/takluyver/subscriptions",
      "organizations_url": "https://api.github.com/users/takluyver/orgs",
      "repos_url": "https://api.github.com/users/takluyver/repos",
      "events_url": "https://api.github.com/users/takluyver/events{/privacy}",
      "received_events_url": "https://api.github.com/users/takluyver/received_events",
      "type": "User",
      "site_admin": false
    },
    "created_at": "2015-03-03T17:54:43Z",
    "updated_at": "2015-03-03T17:54:43Z",
    "author_association": "MEMBER",
    "body": "Does just starting the Python interpreter with `/absolute/path/to/env/bin/python` in a terminal work?\n"
  },
  {
    "url": "https://api.github.com/repos/ipython/ipython/issues/comments/76998343",
    "html_url": "https://github.com/ipython/ipython/issues/7947#issuecomment-76998343",
    "issue_url": "https://api.github.com/repos/ipython/ipython/issues/7947",
    "id": 76998343,
    "node_id": "MDEyOklzc3VlQ29tbWVudDc2OTk4MzQz",
    "user": {
      "login": "cel4",
      "id": 3819470,
      "node_id": "MDQ6VXNlcjM4MTk0NzA=",
      "avatar_url": "https://avatars1.githubusercontent.com/u/3819470?v=4",
      "gravatar_id": "",
      "url": "https://api.github.com/users/cel4",
      "html_url": "https://github.com/cel4",
      "followers_url": "https://api.github.com/users/cel4/followers",
      "following_url": "https://api.github.com/users/cel4/following{/other_user}",
      "gists_url": "https://api.github.com/users/cel4/gists{/gist_id}",
      "starred_url": "https://api.github.com/users/cel4/starred{/owner}{/repo}",
      "subscriptions_url": "https://api.github.com/users/cel4/subscriptions",
      "organizations_url": "https://api.github.com/users/cel4/orgs",
      "repos_url": "https://api.github.com/users/cel4/repos",
      "events_url": "https://api.github.com/users/cel4/events{/privacy}",
      "received_events_url": "https://api.github.com/users/cel4/received_events",
      "type": "User",
      "site_admin": false
    },
    "created_at": "2015-03-03T17:57:59Z",
    "updated_at": "2015-03-03T17:57:59Z",
    "author_association": "CONTRIBUTOR",
    "body": "yes, seems to work fine\n"
  },
  {
    "url": "https://api.github.com/repos/ipython/ipython/issues/comments/76999010",
    "html_url": "https://github.com/ipython/ipython/issues/7947#issuecomment-76999010",
    "issue_url": "https://api.github.com/repos/ipython/ipython/issues/7947",
    "id": 76999010,
    "node_id": "MDEyOklzc3VlQ29tbWVudDc2OTk5MDEw",
    "user": {
      "login": "takluyver",
      "id": 327925,
      "node_id": "MDQ6VXNlcjMyNzkyNQ==",
      "avatar_url": "https://avatars3.githubusercontent.com/u/327925?v=4",
      "gravatar_id": "",
      "url": "https://api.github.com/users/takluyver",
      "html_url": "https://github.com/takluyver",
      "followers_url": "https://api.github.com/users/takluyver/followers",
      "following_url": "https://api.github.com/users/takluyver/following{/other_user}",
      "gists_url": "https://api.github.com/users/takluyver/gists{/gist_id}",
      "starred_url": "https://api.github.com/users/takluyver/starred{/owner}{/repo}",
      "subscriptions_url": "https://api.github.com/users/takluyver/subscriptions",
      "organizations_url": "https://api.github.com/users/takluyver/orgs",
      "repos_url": "https://api.github.com/users/takluyver/repos",
      "events_url": "https://api.github.com/users/takluyver/events{/privacy}",
      "received_events_url": "https://api.github.com/users/takluyver/received_events",
      "type": "User",
      "site_admin": false
    },
    "created_at": "2015-03-03T18:01:11Z",
    "updated_at": "2015-03-03T18:01:11Z",
    "author_association": "MEMBER",
    "body": "Hmm, that's bizarre. And does `/absolute/path/to/env/bin/python -m IPython` work to start IPython?\n"
  },
  {
    "url": "https://api.github.com/repos/ipython/ipython/issues/comments/77000262",
    "html_url": "https://github.com/ipython/ipython/issues/7947#issuecomment-77000262",
    "issue_url": "https://api.github.com/repos/ipython/ipython/issues/7947",
    "id": 77000262,
    "node_id": "MDEyOklzc3VlQ29tbWVudDc3MDAwMjYy",
    "user": {
      "login": "cel4",
      "id": 3819470,
      "node_id": "MDQ6VXNlcjM4MTk0NzA=",
      "avatar_url": "https://avatars1.githubusercontent.com/u/3819470?v=4",
      "gravatar_id": "",
      "url": "https://api.github.com/users/cel4",
      "html_url": "https://github.com/cel4",
      "followers_url": "https://api.github.com/users/cel4/followers",
      "following_url": "https://api.github.com/users/cel4/following{/other_user}",
      "gists_url": "https://api.github.com/users/cel4/gists{/gist_id}",
      "starred_url": "https://api.github.com/users/cel4/starred{/owner}{/repo}",
      "subscriptions_url": "https://api.github.com/users/cel4/subscriptions",
      "organizations_url": "https://api.github.com/users/cel4/orgs",
      "repos_url": "https://api.github.com/users/cel4/repos",
      "events_url": "https://api.github.com/users/cel4/events{/privacy}",
      "received_events_url": "https://api.github.com/users/cel4/received_events",
      "type": "User",
      "site_admin": false
    },
    "created_at": "2015-03-03T18:07:18Z",
    "updated_at": "2015-03-03T18:07:18Z",
    "author_association": "CONTRIBUTOR",
    "body": "yes, works fine as well\n"
  },
  {
    "url": "https://api.github.com/repos/ipython/ipython/issues/comments/77008586",
    "html_url": "https://github.com/ipython/ipython/issues/7947#issuecomment-77008586",
    "issue_url": "https://api.github.com/repos/ipython/ipython/issues/7947",
    "id": 77008586,
    "node_id": "MDEyOklzc3VlQ29tbWVudDc3MDA4NTg2",
    "user": {
      "login": "takluyver",
      "id": 327925,
      "node_id": "MDQ6VXNlcjMyNzkyNQ==",
      "avatar_url": "https://avatars3.githubusercontent.com/u/327925?v=4",
      "gravatar_id": "",
      "url": "https://api.github.com/users/takluyver",
      "html_url": "https://github.com/takluyver",
      "followers_url": "https://api.github.com/users/takluyver/followers",
      "following_url": "https://api.github.com/users/takluyver/following{/other_user}",
      "gists_url": "https://api.github.com/users/takluyver/gists{/gist_id}",
      "starred_url": "https://api.github.com/users/takluyver/starred{/owner}{/repo}",
      "subscriptions_url": "https://api.github.com/users/takluyver/subscriptions",
      "organizations_url": "https://api.github.com/users/takluyver/orgs",
      "repos_url": "https://api.github.com/users/takluyver/repos",
      "events_url": "https://api.github.com/users/takluyver/events{/privacy}",
      "received_events_url": "https://api.github.com/users/takluyver/received_events",
      "type": "User",
      "site_admin": false
    },
    "created_at": "2015-03-03T18:50:15Z",
    "updated_at": "2015-03-03T18:50:15Z",
    "author_association": "MEMBER",
    "body": ":confused: That should be more or less equivalent to what the notebook is doing to launch that kernel. I'm not sure why Python would fail to start in one situation but not the other.\n"
  },
  {
    "url": "https://api.github.com/repos/ipython/ipython/issues/comments/77021530",
    "html_url": "https://github.com/ipython/ipython/issues/7947#issuecomment-77021530",
    "issue_url": "https://api.github.com/repos/ipython/ipython/issues/7947",
    "id": 77021530,
    "node_id": "MDEyOklzc3VlQ29tbWVudDc3MDIxNTMw",
    "user": {
      "login": "Carreau",
      "id": 335567,
      "node_id": "MDQ6VXNlcjMzNTU2Nw==",
      "avatar_url": "https://avatars3.githubusercontent.com/u/335567?v=4",
      "gravatar_id": "",
      "url": "https://api.github.com/users/Carreau",
      "html_url": "https://github.com/Carreau",
      "followers_url": "https://api.github.com/users/Carreau/followers",
      "following_url": "https://api.github.com/users/Carreau/following{/other_user}",
      "gists_url": "https://api.github.com/users/Carreau/gists{/gist_id}",
      "starred_url": "https://api.github.com/users/Carreau/starred{/owner}{/repo}",
      "subscriptions_url": "https://api.github.com/users/Carreau/subscriptions",
      "organizations_url": "https://api.github.com/users/Carreau/orgs",
      "repos_url": "https://api.github.com/users/Carreau/repos",
      "events_url": "https://api.github.com/users/Carreau/events{/privacy}",
      "received_events_url": "https://api.github.com/users/Carreau/received_events",
      "type": "User",
      "site_admin": false
    },
    "created_at": "2015-03-03T19:56:05Z",
    "updated_at": "2015-03-03T19:56:05Z",
    "author_association": "MEMBER",
    "body": "Could the env variable in the subprocess not be the same ? \n"
  },
  {
    "url": "https://api.github.com/repos/ipython/ipython/issues/comments/77023580",
    "html_url": "https://github.com/ipython/ipython/issues/7947#issuecomment-77023580",
    "issue_url": "https://api.github.com/repos/ipython/ipython/issues/7947",
    "id": 77023580,
    "node_id": "MDEyOklzc3VlQ29tbWVudDc3MDIzNTgw",
    "user": {
      "login": "takluyver",
      "id": 327925,
      "node_id": "MDQ6VXNlcjMyNzkyNQ==",
      "avatar_url": "https://avatars3.githubusercontent.com/u/327925?v=4",
      "gravatar_id": "",
      "url": "https://api.github.com/users/takluyver",
      "html_url": "https://github.com/takluyver",
      "followers_url": "https://api.github.com/users/takluyver/followers",
      "following_url": "https://api.github.com/users/takluyver/following{/other_user}",
      "gists_url": "https://api.github.com/users/takluyver/gists{/gist_id}",
      "starred_url": "https://api.github.com/users/takluyver/starred{/owner}{/repo}",
      "subscriptions_url": "https://api.github.com/users/takluyver/subscriptions",
      "organizations_url": "https://api.github.com/users/takluyver/orgs",
      "repos_url": "https://api.github.com/users/takluyver/repos",
      "events_url": "https://api.github.com/users/takluyver/events{/privacy}",
      "received_events_url": "https://api.github.com/users/takluyver/received_events",
      "type": "User",
      "site_admin": false
    },
    "created_at": "2015-03-03T20:06:41Z",
    "updated_at": "2015-03-03T20:06:41Z",
    "author_association": "MEMBER",
    "body": "That could be. Are you starting the notebook from a terminal, or some other way?\n"
  },
  {
    "url": "https://api.github.com/repos/ipython/ipython/issues/comments/77149864",
    "html_url": "https://github.com/ipython/ipython/issues/7947#issuecomment-77149864",
    "issue_url": "https://api.github.com/repos/ipython/ipython/issues/7947",
    "id": 77149864,
    "node_id": "MDEyOklzc3VlQ29tbWVudDc3MTQ5ODY0",
    "user": {
      "login": "cel4",
      "id": 3819470,
      "node_id": "MDQ6VXNlcjM4MTk0NzA=",
      "avatar_url": "https://avatars1.githubusercontent.com/u/3819470?v=4",
      "gravatar_id": "",
      "url": "https://api.github.com/users/cel4",
      "html_url": "https://github.com/cel4",
      "followers_url": "https://api.github.com/users/cel4/followers",
      "following_url": "https://api.github.com/users/cel4/following{/other_user}",
      "gists_url": "https://api.github.com/users/cel4/gists{/gist_id}",
      "starred_url": "https://api.github.com/users/cel4/starred{/owner}{/repo}",
      "subscriptions_url": "https://api.github.com/users/cel4/subscriptions",
      "organizations_url": "https://api.github.com/users/cel4/orgs",
      "repos_url": "https://api.github.com/users/cel4/repos",
      "events_url": "https://api.github.com/users/cel4/events{/privacy}",
      "received_events_url": "https://api.github.com/users/cel4/received_events",
      "type": "User",
      "site_admin": false
    },
    "created_at": "2015-03-04T12:32:42Z",
    "updated_at": "2015-03-04T12:34:05Z",
    "author_association": "CONTRIBUTOR",
    "body": "Yes simply `ipython notebook` in my terminal. I think knowing if it's just me or if you can reproduce that with a `virtualenv` would help a lot for debugging.\n"
  },
  {
    "url": "https://api.github.com/repos/ipython/ipython/issues/comments/77452344",
    "html_url": "https://github.com/ipython/ipython/issues/7947#issuecomment-77452344",
    "issue_url": "https://api.github.com/repos/ipython/ipython/issues/7947",
    "id": 77452344,
    "node_id": "MDEyOklzc3VlQ29tbWVudDc3NDUyMzQ0",
    "user": {
      "login": "takluyver",
      "id": 327925,
      "node_id": "MDQ6VXNlcjMyNzkyNQ==",
      "avatar_url": "https://avatars3.githubusercontent.com/u/327925?v=4",
      "gravatar_id": "",
      "url": "https://api.github.com/users/takluyver",
      "html_url": "https://github.com/takluyver",
      "followers_url": "https://api.github.com/users/takluyver/followers",
      "following_url": "https://api.github.com/users/takluyver/following{/other_user}",
      "gists_url": "https://api.github.com/users/takluyver/gists{/gist_id}",
      "starred_url": "https://api.github.com/users/takluyver/starred{/owner}{/repo}",
      "subscriptions_url": "https://api.github.com/users/takluyver/subscriptions",
      "organizations_url": "https://api.github.com/users/takluyver/orgs",
      "repos_url": "https://api.github.com/users/takluyver/repos",
      "events_url": "https://api.github.com/users/takluyver/events{/privacy}",
      "received_events_url": "https://api.github.com/users/takluyver/received_events",
      "type": "User",
      "site_admin": false
    },
    "created_at": "2015-03-05T21:10:20Z",
    "updated_at": "2015-03-05T21:10:20Z",
    "author_association": "MEMBER",
    "body": "I've just tried with a virtualenv, and it works exactly as I'd expect. Have you tested with an actual virtualenv, or only with conda envs?\n"
  },
  {
    "url": "https://api.github.com/repos/ipython/ipython/issues/comments/77453506",
    "html_url": "https://github.com/ipython/ipython/issues/7947#issuecomment-77453506",
    "issue_url": "https://api.github.com/repos/ipython/ipython/issues/7947",
    "id": 77453506,
    "node_id": "MDEyOklzc3VlQ29tbWVudDc3NDUzNTA2",
    "user": {
      "login": "minrk",
      "id": 151929,
      "node_id": "MDQ6VXNlcjE1MTkyOQ==",
      "avatar_url": "https://avatars1.githubusercontent.com/u/151929?v=4",
      "gravatar_id": "",
      "url": "https://api.github.com/users/minrk",
      "html_url": "https://github.com/minrk",
      "followers_url": "https://api.github.com/users/minrk/followers",
      "following_url": "https://api.github.com/users/minrk/following{/other_user}",
      "gists_url": "https://api.github.com/users/minrk/gists{/gist_id}",
      "starred_url": "https://api.github.com/users/minrk/starred{/owner}{/repo}",
      "subscriptions_url": "https://api.github.com/users/minrk/subscriptions",
      "organizations_url": "https://api.github.com/users/minrk/orgs",
      "repos_url": "https://api.github.com/users/minrk/repos",
      "events_url": "https://api.github.com/users/minrk/events{/privacy}",
      "received_events_url": "https://api.github.com/users/minrk/received_events",
      "type": "User",
      "site_admin": false
    },
    "created_at": "2015-03-05T21:16:57Z",
    "updated_at": "2015-03-05T21:16:57Z",
    "author_association": "MEMBER",
    "body": "I use kernelspecs for conda envs as well, and haven't had an issue.\n\n@cel4 can you start regular IPython this way?\n\n```\n/path/to/env/bin/python -m IPython\n```\n"
  },
  {
    "url": "https://api.github.com/repos/ipython/ipython/issues/comments/77453740",
    "html_url": "https://github.com/ipython/ipython/issues/7947#issuecomment-77453740",
    "issue_url": "https://api.github.com/repos/ipython/ipython/issues/7947",
    "id": 77453740,
    "node_id": "MDEyOklzc3VlQ29tbWVudDc3NDUzNzQw",
    "user": {
      "login": "takluyver",
      "id": 327925,
      "node_id": "MDQ6VXNlcjMyNzkyNQ==",
      "avatar_url": "https://avatars3.githubusercontent.com/u/327925?v=4",
      "gravatar_id": "",
      "url": "https://api.github.com/users/takluyver",
      "html_url": "https://github.com/takluyver",
      "followers_url": "https://api.github.com/users/takluyver/followers",
      "following_url": "https://api.github.com/users/takluyver/following{/other_user}",
      "gists_url": "https://api.github.com/users/takluyver/gists{/gist_id}",
      "starred_url": "https://api.github.com/users/takluyver/starred{/owner}{/repo}",
      "subscriptions_url": "https://api.github.com/users/takluyver/subscriptions",
      "organizations_url": "https://api.github.com/users/takluyver/orgs",
      "repos_url": "https://api.github.com/users/takluyver/repos",
      "events_url": "https://api.github.com/users/takluyver/events{/privacy}",
      "received_events_url": "https://api.github.com/users/takluyver/received_events",
      "type": "User",
      "site_admin": false
    },
    "created_at": "2015-03-05T21:18:17Z",
    "updated_at": "2015-03-05T21:18:17Z",
    "author_association": "MEMBER",
    "body": "already checked that ;-) https://github.com/ipython/ipython/issues/7947#issuecomment-76999010\n"
  },
  {
    "url": "https://api.github.com/repos/ipython/ipython/issues/comments/77466221",
    "html_url": "https://github.com/ipython/ipython/issues/7947#issuecomment-77466221",
    "issue_url": "https://api.github.com/repos/ipython/ipython/issues/7947",
    "id": 77466221,
    "node_id": "MDEyOklzc3VlQ29tbWVudDc3NDY2MjIx",
    "user": {
      "login": "minrk",
      "id": 151929,
      "node_id": "MDQ6VXNlcjE1MTkyOQ==",
      "avatar_url": "https://avatars1.githubusercontent.com/u/151929?v=4",
      "gravatar_id": "",
      "url": "https://api.github.com/users/minrk",
      "html_url": "https://github.com/minrk",
      "followers_url": "https://api.github.com/users/minrk/followers",
      "following_url": "https://api.github.com/users/minrk/following{/other_user}",
      "gists_url": "https://api.github.com/users/minrk/gists{/gist_id}",
      "starred_url": "https://api.github.com/users/minrk/starred{/owner}{/repo}",
      "subscriptions_url": "https://api.github.com/users/minrk/subscriptions",
      "organizations_url": "https://api.github.com/users/minrk/orgs",
      "repos_url": "https://api.github.com/users/minrk/repos",
      "events_url": "https://api.github.com/users/minrk/events{/privacy}",
      "received_events_url": "https://api.github.com/users/minrk/received_events",
      "type": "User",
      "site_admin": false
    },
    "created_at": "2015-03-05T22:28:54Z",
    "updated_at": "2015-03-05T22:28:54Z",
    "author_association": "MEMBER",
    "body": "Sorry, not paying enough attention. I do use conda envs with kernelspecs regularly, so I'm not sure what would be different. Maybe check env variables?\n"
  },
  {
    "url": "https://api.github.com/repos/ipython/ipython/issues/comments/77521215",
    "html_url": "https://github.com/ipython/ipython/issues/7947#issuecomment-77521215",
    "issue_url": "https://api.github.com/repos/ipython/ipython/issues/7947",
    "id": 77521215,
    "node_id": "MDEyOklzc3VlQ29tbWVudDc3NTIxMjE1",
    "user": {
      "login": "cel4",
      "id": 3819470,
      "node_id": "MDQ6VXNlcjM4MTk0NzA=",
      "avatar_url": "https://avatars1.githubusercontent.com/u/3819470?v=4",
      "gravatar_id": "",
      "url": "https://api.github.com/users/cel4",
      "html_url": "https://github.com/cel4",
      "followers_url": "https://api.github.com/users/cel4/followers",
      "following_url": "https://api.github.com/users/cel4/following{/other_user}",
      "gists_url": "https://api.github.com/users/cel4/gists{/gist_id}",
      "starred_url": "https://api.github.com/users/cel4/starred{/owner}{/repo}",
      "subscriptions_url": "https://api.github.com/users/cel4/subscriptions",
      "organizations_url": "https://api.github.com/users/cel4/orgs",
      "repos_url": "https://api.github.com/users/cel4/repos",
      "events_url": "https://api.github.com/users/cel4/events{/privacy}",
      "received_events_url": "https://api.github.com/users/cel4/received_events",
      "type": "User",
      "site_admin": false
    },
    "created_at": "2015-03-06T08:07:45Z",
    "updated_at": "2015-03-06T08:07:45Z",
    "author_association": "CONTRIBUTOR",
    "body": "Uff, something seems to be broken here...\n\nI'm trying to troubleshoot the problem, but new weird errors coming up:\n\n```\n[I 08:53:26.102 NotebookApp] Using existing profile dir: '/Users/ch/.ipython/profile_default'\n[I 08:53:26.106 NotebookApp] Using MathJax from CDN: https://cdn.mathjax.org/mathjax/latest/MathJax.js\n[I 08:53:26.129 NotebookApp] Serving notebooks from local directory: /private/tmp\n[I 08:53:26.130 NotebookApp] 0 active kernels\n[I 08:53:26.130 NotebookApp] The IPython Notebook is running at: http://localhost:8888/\n[I 08:53:26.130 NotebookApp] Use Control-C to stop this server and shut down all kernels (twice to skip confirmation).\n[I 08:53:31.152 NotebookApp] Creating new notebook in\n[I 08:53:32.346 NotebookApp] Kernel started: f2cfa26d-4c6e-4a25-9f4d-52ff7e5e36cc\n/Users/ch/miniconda/envs/sci34/bin/python: No module named IPython\n[I 08:53:35.348 NotebookApp] KernelRestarter: restarting kernel (1/5)\n/Users/ch/miniconda/envs/sci34/bin/python: No module named IPython\n[I 08:53:38.358 NotebookApp] KernelRestarter: restarting kernel (2/5)\n/Users/ch/miniconda/envs/sci34/bin/python: No module named IPython\n[I 08:53:41.365 NotebookApp] KernelRestarter: restarting kernel (3/5)\n/Users/ch/miniconda/envs/sci34/bin/python: No module named IPython\n[W 08:53:42.399 NotebookApp] Timeout waiting for kernel_info reply from f2cfa26d-4c6e-4a25-9f4d-52ff7e5e36cc\n[I 08:53:44.376 NotebookApp] KernelRestarter: restarting kernel (4/5)\nWARNING:root:kernel f2cfa26d-4c6e-4a25-9f4d-52ff7e5e36cc restarted\n/Users/ch/miniconda/envs/sci34/bin/python: No module named IPython\n[W 08:53:47.386 NotebookApp] KernelRestarter: restart failed\n[W 08:53:47.386 NotebookApp] Kernel f2cfa26d-4c6e-4a25-9f4d-52ff7e5e36cc died, removing from map.\nERROR:root:kernel f2cfa26d-4c6e-4a25-9f4d-52ff7e5e36cc restarted failed!\n[W 08:53:47.399 NotebookApp] Kernel deleted before session\n[W 08:53:47.400 NotebookApp] 410 DELETE /api/sessions/91849bea-a081-4e5c-b29a-47474b7d3acf (::1) 1.37ms referer=http://localhost:8888/notebooks/Untitled13.ipynb?kernel_name=testkernel\n```\n\nWhere are those `/Users/ch/miniconda/envs/sci34/bin/python: No module named IPython`  messages raised?\n\n`/Users/ch/miniconda/envs/sci34/bin/python -m IPython --version`  prints `3.0.0`. \n"
  },
  {
    "url": "https://api.github.com/repos/ipython/ipython/issues/comments/77598418",
    "html_url": "https://github.com/ipython/ipython/issues/7947#issuecomment-77598418",
    "issue_url": "https://api.github.com/repos/ipython/ipython/issues/7947",
    "id": 77598418,
    "node_id": "MDEyOklzc3VlQ29tbWVudDc3NTk4NDE4",
    "user": {
      "login": "minrk",
      "id": 151929,
      "node_id": "MDQ6VXNlcjE1MTkyOQ==",
      "avatar_url": "https://avatars1.githubusercontent.com/u/151929?v=4",
      "gravatar_id": "",
      "url": "https://api.github.com/users/minrk",
      "html_url": "https://github.com/minrk",
      "followers_url": "https://api.github.com/users/minrk/followers",
      "following_url": "https://api.github.com/users/minrk/following{/other_user}",
      "gists_url": "https://api.github.com/users/minrk/gists{/gist_id}",
      "starred_url": "https://api.github.com/users/minrk/starred{/owner}{/repo}",
      "subscriptions_url": "https://api.github.com/users/minrk/subscriptions",
      "organizations_url": "https://api.github.com/users/minrk/orgs",
      "repos_url": "https://api.github.com/users/minrk/repos",
      "events_url": "https://api.github.com/users/minrk/events{/privacy}",
      "received_events_url": "https://api.github.com/users/minrk/received_events",
      "type": "User",
      "site_admin": false
    },
    "created_at": "2015-03-06T17:24:46Z",
    "updated_at": "2015-03-06T17:24:46Z",
    "author_association": "MEMBER",
    "body": "Can you run the server with `--debug`?\n"
  },
  {
    "url": "https://api.github.com/repos/ipython/ipython/issues/comments/77708797",
    "html_url": "https://github.com/ipython/ipython/issues/7947#issuecomment-77708797",
    "issue_url": "https://api.github.com/repos/ipython/ipython/issues/7947",
    "id": 77708797,
    "node_id": "MDEyOklzc3VlQ29tbWVudDc3NzA4Nzk3",
    "user": {
      "login": "cel4",
      "id": 3819470,
      "node_id": "MDQ6VXNlcjM4MTk0NzA=",
      "avatar_url": "https://avatars1.githubusercontent.com/u/3819470?v=4",
      "gravatar_id": "",
      "url": "https://api.github.com/users/cel4",
      "html_url": "https://github.com/cel4",
      "followers_url": "https://api.github.com/users/cel4/followers",
      "following_url": "https://api.github.com/users/cel4/following{/other_user}",
      "gists_url": "https://api.github.com/users/cel4/gists{/gist_id}",
      "starred_url": "https://api.github.com/users/cel4/starred{/owner}{/repo}",
      "subscriptions_url": "https://api.github.com/users/cel4/subscriptions",
      "organizations_url": "https://api.github.com/users/cel4/orgs",
      "repos_url": "https://api.github.com/users/cel4/repos",
      "events_url": "https://api.github.com/users/cel4/events{/privacy}",
      "received_events_url": "https://api.github.com/users/cel4/received_events",
      "type": "User",
      "site_admin": false
    },
    "created_at": "2015-03-07T20:37:19Z",
    "updated_at": "2015-03-07T20:37:19Z",
    "author_association": "CONTRIBUTOR",
    "body": "So it seems that if I start ipython in my activated `sci33` conda environment, everything works fine. However it does not seem to be possible to start this kernel when I'm in another conda or virtualenv environment.\n\nIt seems that the path to the site-packages is somehow screwed. I guess printing `site.getsitepackages()` would give some weird results. Yet, I understand too little from the kernel logic to debug that.\n\nHere is the debug log. I didn't find anything suspicious.\nhttps://gist.github.com/cel4/f1925979dcadfbfe9322\n"
  },
  {
    "url": "https://api.github.com/repos/ipython/ipython/issues/comments/77711136",
    "html_url": "https://github.com/ipython/ipython/issues/7947#issuecomment-77711136",
    "issue_url": "https://api.github.com/repos/ipython/ipython/issues/7947",
    "id": 77711136,
    "node_id": "MDEyOklzc3VlQ29tbWVudDc3NzExMTM2",
    "user": {
      "login": "minrk",
      "id": 151929,
      "node_id": "MDQ6VXNlcjE1MTkyOQ==",
      "avatar_url": "https://avatars1.githubusercontent.com/u/151929?v=4",
      "gravatar_id": "",
      "url": "https://api.github.com/users/minrk",
      "html_url": "https://github.com/minrk",
      "followers_url": "https://api.github.com/users/minrk/followers",
      "following_url": "https://api.github.com/users/minrk/following{/other_user}",
      "gists_url": "https://api.github.com/users/minrk/gists{/gist_id}",
      "starred_url": "https://api.github.com/users/minrk/starred{/owner}{/repo}",
      "subscriptions_url": "https://api.github.com/users/minrk/subscriptions",
      "organizations_url": "https://api.github.com/users/minrk/orgs",
      "repos_url": "https://api.github.com/users/minrk/repos",
      "events_url": "https://api.github.com/users/minrk/events{/privacy}",
      "received_events_url": "https://api.github.com/users/minrk/received_events",
      "type": "User",
      "site_admin": false
    },
    "created_at": "2015-03-07T21:31:00Z",
    "updated_at": "2015-03-07T21:31:00Z",
    "author_association": "MEMBER",
    "body": "Can you share your environment variables (minus anything sensitive)? I suspect there might be something funny going on there.\n"
  },
  {
    "url": "https://api.github.com/repos/ipython/ipython/issues/comments/77712481",
    "html_url": "https://github.com/ipython/ipython/issues/7947#issuecomment-77712481",
    "issue_url": "https://api.github.com/repos/ipython/ipython/issues/7947",
    "id": 77712481,
    "node_id": "MDEyOklzc3VlQ29tbWVudDc3NzEyNDgx",
    "user": {
      "login": "cel4",
      "id": 3819470,
      "node_id": "MDQ6VXNlcjM4MTk0NzA=",
      "avatar_url": "https://avatars1.githubusercontent.com/u/3819470?v=4",
      "gravatar_id": "",
      "url": "https://api.github.com/users/cel4",
      "html_url": "https://github.com/cel4",
      "followers_url": "https://api.github.com/users/cel4/followers",
      "following_url": "https://api.github.com/users/cel4/following{/other_user}",
      "gists_url": "https://api.github.com/users/cel4/gists{/gist_id}",
      "starred_url": "https://api.github.com/users/cel4/starred{/owner}{/repo}",
      "subscriptions_url": "https://api.github.com/users/cel4/subscriptions",
      "organizations_url": "https://api.github.com/users/cel4/orgs",
      "repos_url": "https://api.github.com/users/cel4/repos",
      "events_url": "https://api.github.com/users/cel4/events{/privacy}",
      "received_events_url": "https://api.github.com/users/cel4/received_events",
      "type": "User",
      "site_admin": false
    },
    "created_at": "2015-03-07T21:52:48Z",
    "updated_at": "2015-03-07T21:52:48Z",
    "author_association": "CONTRIBUTOR",
    "body": "Here you go: https://gist.github.com/cel4/ad8a35d452814a573108\n"
  },
  {
    "url": "https://api.github.com/repos/ipython/ipython/issues/comments/84331895",
    "html_url": "https://github.com/ipython/ipython/issues/7947#issuecomment-84331895",
    "issue_url": "https://api.github.com/repos/ipython/ipython/issues/7947",
    "id": 84331895,
    "node_id": "MDEyOklzc3VlQ29tbWVudDg0MzMxODk1",
    "user": {
      "login": "cel4",
      "id": 3819470,
      "node_id": "MDQ6VXNlcjM4MTk0NzA=",
      "avatar_url": "https://avatars1.githubusercontent.com/u/3819470?v=4",
      "gravatar_id": "",
      "url": "https://api.github.com/users/cel4",
      "html_url": "https://github.com/cel4",
      "followers_url": "https://api.github.com/users/cel4/followers",
      "following_url": "https://api.github.com/users/cel4/following{/other_user}",
      "gists_url": "https://api.github.com/users/cel4/gists{/gist_id}",
      "starred_url": "https://api.github.com/users/cel4/starred{/owner}{/repo}",
      "subscriptions_url": "https://api.github.com/users/cel4/subscriptions",
      "organizations_url": "https://api.github.com/users/cel4/orgs",
      "repos_url": "https://api.github.com/users/cel4/repos",
      "events_url": "https://api.github.com/users/cel4/events{/privacy}",
      "received_events_url": "https://api.github.com/users/cel4/received_events",
      "type": "User",
      "site_admin": false
    },
    "created_at": "2015-03-21T12:51:26Z",
    "updated_at": "2015-03-21T12:51:26Z",
    "author_association": "CONTRIBUTOR",
    "body": "I had some time for some further investigation: I only see this problem on my mac. I cannot reproduce it on a ubuntu box.\n\nHow to reproduce it (with miniconda):\n\nThe kernel environment:\n\n```\nconda create -n kernel python=2.7 ipython-notebook\nsource activate kernel\nipython kernelspec install-self --user\n```\n\nThe notebook environment:\n\n```\nconda create -n ipy python=3.4 ipython-notebook\nsource activate ipy\nipython notebook\n```\n\nIs someone on OSX and has the time to check if it's reproducible, or just me?\n"
  },
  {
    "url": "https://api.github.com/repos/ipython/ipython/issues/comments/94812978",
    "html_url": "https://github.com/ipython/ipython/issues/7947#issuecomment-94812978",
    "issue_url": "https://api.github.com/repos/ipython/ipython/issues/7947",
    "id": 94812978,
    "node_id": "MDEyOklzc3VlQ29tbWVudDk0ODEyOTc4",
    "user": {
      "login": "cel4",
      "id": 3819470,
      "node_id": "MDQ6VXNlcjM4MTk0NzA=",
      "avatar_url": "https://avatars1.githubusercontent.com/u/3819470?v=4",
      "gravatar_id": "",
      "url": "https://api.github.com/users/cel4",
      "html_url": "https://github.com/cel4",
      "followers_url": "https://api.github.com/users/cel4/followers",
      "following_url": "https://api.github.com/users/cel4/following{/other_user}",
      "gists_url": "https://api.github.com/users/cel4/gists{/gist_id}",
      "starred_url": "https://api.github.com/users/cel4/starred{/owner}{/repo}",
      "subscriptions_url": "https://api.github.com/users/cel4/subscriptions",
      "organizations_url": "https://api.github.com/users/cel4/orgs",
      "repos_url": "https://api.github.com/users/cel4/repos",
      "events_url": "https://api.github.com/users/cel4/events{/privacy}",
      "received_events_url": "https://api.github.com/users/cel4/received_events",
      "type": "User",
      "site_admin": false
    },
    "created_at": "2015-04-21T14:24:10Z",
    "updated_at": "2015-04-21T14:24:10Z",
    "author_association": "CONTRIBUTOR",
    "body": "This is still bugging me - anyone with a mac here who can try to reproduce this?\n"
  },
  {
    "url": "https://api.github.com/repos/ipython/ipython/issues/comments/100888288",
    "html_url": "https://github.com/ipython/ipython/issues/7947#issuecomment-100888288",
    "issue_url": "https://api.github.com/repos/ipython/ipython/issues/7947",
    "id": 100888288,
    "node_id": "MDEyOklzc3VlQ29tbWVudDEwMDg4ODI4OA==",
    "user": {
      "login": "jrderuiter",
      "id": 307739,
      "node_id": "MDQ6VXNlcjMwNzczOQ==",
      "avatar_url": "https://avatars0.githubusercontent.com/u/307739?v=4",
      "gravatar_id": "",
      "url": "https://api.github.com/users/jrderuiter",
      "html_url": "https://github.com/jrderuiter",
      "followers_url": "https://api.github.com/users/jrderuiter/followers",
      "following_url": "https://api.github.com/users/jrderuiter/following{/other_user}",
      "gists_url": "https://api.github.com/users/jrderuiter/gists{/gist_id}",
      "starred_url": "https://api.github.com/users/jrderuiter/starred{/owner}{/repo}",
      "subscriptions_url": "https://api.github.com/users/jrderuiter/subscriptions",
      "organizations_url": "https://api.github.com/users/jrderuiter/orgs",
      "repos_url": "https://api.github.com/users/jrderuiter/repos",
      "events_url": "https://api.github.com/users/jrderuiter/events{/privacy}",
      "received_events_url": "https://api.github.com/users/jrderuiter/received_events",
      "type": "User",
      "site_admin": false
    },
    "created_at": "2015-05-11T12:11:08Z",
    "updated_at": "2015-05-11T12:11:23Z",
    "author_association": "NONE",
    "body": "I have the same issue on my Mac. Using Anaconda 3.4 as default environment, trying to use a Python 2.7 from a conda environment as a kernel.\n\n```\nCould not find platform independent libraries <prefix>\nCould not find platform dependent libraries <exec_prefix>\nConsider setting $PYTHONHOME to <prefix>[:<exec_prefix>]\nImportError: No module named site\n```\n"
  },
  {
    "url": "https://api.github.com/repos/ipython/ipython/issues/comments/106928221",
    "html_url": "https://github.com/ipython/ipython/issues/7947#issuecomment-106928221",
    "issue_url": "https://api.github.com/repos/ipython/ipython/issues/7947",
    "id": 106928221,
    "node_id": "MDEyOklzc3VlQ29tbWVudDEwNjkyODIyMQ==",
    "user": {
      "login": "cel4",
      "id": 3819470,
      "node_id": "MDQ6VXNlcjM4MTk0NzA=",
      "avatar_url": "https://avatars1.githubusercontent.com/u/3819470?v=4",
      "gravatar_id": "",
      "url": "https://api.github.com/users/cel4",
      "html_url": "https://github.com/cel4",
      "followers_url": "https://api.github.com/users/cel4/followers",
      "following_url": "https://api.github.com/users/cel4/following{/other_user}",
      "gists_url": "https://api.github.com/users/cel4/gists{/gist_id}",
      "starred_url": "https://api.github.com/users/cel4/starred{/owner}{/repo}",
      "subscriptions_url": "https://api.github.com/users/cel4/subscriptions",
      "organizations_url": "https://api.github.com/users/cel4/orgs",
      "repos_url": "https://api.github.com/users/cel4/repos",
      "events_url": "https://api.github.com/users/cel4/events{/privacy}",
      "received_events_url": "https://api.github.com/users/cel4/received_events",
      "type": "User",
      "site_admin": false
    },
    "created_at": "2015-05-29T20:34:28Z",
    "updated_at": "2015-05-29T20:34:28Z",
    "author_association": "CONTRIBUTOR",
    "body": "Okay, I nuked all my extra python kernels and installed new ones. This narrowed the problem down to this rather interesting observation:\n\nWhen I start the notebook server in a `ipython-3.x` environment, everything works as expected. I can start start my self-defined `python2` and `python3` kernels.\n\nWhen I start the notebook server in a `python-2.x` environment, I can start kernels in `py27` environments, but not kernels in any `py34` environment.\n\nI get the `Could not find platform independent libraries <prefix>` error in this case.\n\nBut again, this issue does not seem to be reproducible on my ubuntu box. This already narrows the problem down to the point that it's not the environments themselves, but the fact that `python2` calls `python3`.\n\nThis is where I am stuck now.\n"
  },
  {
    "url": "https://api.github.com/repos/ipython/ipython/issues/comments/110456221",
    "html_url": "https://github.com/ipython/ipython/issues/7947#issuecomment-110456221",
    "issue_url": "https://api.github.com/repos/ipython/ipython/issues/7947",
    "id": 110456221,
    "node_id": "MDEyOklzc3VlQ29tbWVudDExMDQ1NjIyMQ==",
    "user": {
      "login": "cel4",
      "id": 3819470,
      "node_id": "MDQ6VXNlcjM4MTk0NzA=",
      "avatar_url": "https://avatars1.githubusercontent.com/u/3819470?v=4",
      "gravatar_id": "",
      "url": "https://api.github.com/users/cel4",
      "html_url": "https://github.com/cel4",
      "followers_url": "https://api.github.com/users/cel4/followers",
      "following_url": "https://api.github.com/users/cel4/following{/other_user}",
      "gists_url": "https://api.github.com/users/cel4/gists{/gist_id}",
      "starred_url": "https://api.github.com/users/cel4/starred{/owner}{/repo}",
      "subscriptions_url": "https://api.github.com/users/cel4/subscriptions",
      "organizations_url": "https://api.github.com/users/cel4/orgs",
      "repos_url": "https://api.github.com/users/cel4/repos",
      "events_url": "https://api.github.com/users/cel4/events{/privacy}",
      "received_events_url": "https://api.github.com/users/cel4/received_events",
      "type": "User",
      "site_admin": false
    },
    "created_at": "2015-06-09T18:29:24Z",
    "updated_at": "2015-06-09T19:39:08Z",
    "author_association": "CONTRIBUTOR",
    "body": "This problem boils down to this:\n\n``` python\nimport subprocess\nfrom subprocess import Popen\ncmd = [\n    '/usr/local/bin/python',\n    '-m', 'IPython.kernel',\n    '-f', '/tmp/test_kernel.json'\n]\np = Popen(cmd, stdout=subprocess.PIPE, stderr=subprocess.PIPE)\nout, err = p.communicate()\nprint(err.decode(\"utf-8\"))\n```\n\n-- `/Users/ch/miniconda/envs/sci34/bin/python: No module named IPython`\n"
  },
  {
    "url": "https://api.github.com/repos/ipython/ipython/issues/comments/110465475",
    "html_url": "https://github.com/ipython/ipython/issues/7947#issuecomment-110465475",
    "issue_url": "https://api.github.com/repos/ipython/ipython/issues/7947",
    "id": 110465475,
    "node_id": "MDEyOklzc3VlQ29tbWVudDExMDQ2NTQ3NQ==",
    "user": {
      "login": "takluyver",
      "id": 327925,
      "node_id": "MDQ6VXNlcjMyNzkyNQ==",
      "avatar_url": "https://avatars3.githubusercontent.com/u/327925?v=4",
      "gravatar_id": "",
      "url": "https://api.github.com/users/takluyver",
      "html_url": "https://github.com/takluyver",
      "followers_url": "https://api.github.com/users/takluyver/followers",
      "following_url": "https://api.github.com/users/takluyver/following{/other_user}",
      "gists_url": "https://api.github.com/users/takluyver/gists{/gist_id}",
      "starred_url": "https://api.github.com/users/takluyver/starred{/owner}{/repo}",
      "subscriptions_url": "https://api.github.com/users/takluyver/subscriptions",
      "organizations_url": "https://api.github.com/users/takluyver/orgs",
      "repos_url": "https://api.github.com/users/takluyver/repos",
      "events_url": "https://api.github.com/users/takluyver/events{/privacy}",
      "received_events_url": "https://api.github.com/users/takluyver/received_events",
      "type": "User",
      "site_admin": false
    },
    "created_at": "2015-06-09T19:02:01Z",
    "updated_at": "2015-06-09T19:02:01Z",
    "author_association": "MEMBER",
    "body": "So you're telling it `/usr/local/bin/python` but it's trying to use `...envs/sci34/bin/python`? That's very strange.\n"
  },
  {
    "url": "https://api.github.com/repos/ipython/ipython/issues/comments/110466319",
    "html_url": "https://github.com/ipython/ipython/issues/7947#issuecomment-110466319",
    "issue_url": "https://api.github.com/repos/ipython/ipython/issues/7947",
    "id": 110466319,
    "node_id": "MDEyOklzc3VlQ29tbWVudDExMDQ2NjMxOQ==",
    "user": {
      "login": "minrk",
      "id": 151929,
      "node_id": "MDQ6VXNlcjE1MTkyOQ==",
      "avatar_url": "https://avatars1.githubusercontent.com/u/151929?v=4",
      "gravatar_id": "",
      "url": "https://api.github.com/users/minrk",
      "html_url": "https://github.com/minrk",
      "followers_url": "https://api.github.com/users/minrk/followers",
      "following_url": "https://api.github.com/users/minrk/following{/other_user}",
      "gists_url": "https://api.github.com/users/minrk/gists{/gist_id}",
      "starred_url": "https://api.github.com/users/minrk/starred{/owner}{/repo}",
      "subscriptions_url": "https://api.github.com/users/minrk/subscriptions",
      "organizations_url": "https://api.github.com/users/minrk/orgs",
      "repos_url": "https://api.github.com/users/minrk/repos",
      "events_url": "https://api.github.com/users/minrk/events{/privacy}",
      "received_events_url": "https://api.github.com/users/minrk/received_events",
      "type": "User",
      "site_admin": false
    },
    "created_at": "2015-06-09T19:05:46Z",
    "updated_at": "2015-06-09T19:05:46Z",
    "author_association": "MEMBER",
    "body": "What do you get from `file /usr/local/bin/python`?\n"
  },
  {
    "url": "https://api.github.com/repos/ipython/ipython/issues/comments/110466516",
    "html_url": "https://github.com/ipython/ipython/issues/7947#issuecomment-110466516",
    "issue_url": "https://api.github.com/repos/ipython/ipython/issues/7947",
    "id": 110466516,
    "node_id": "MDEyOklzc3VlQ29tbWVudDExMDQ2NjUxNg==",
    "user": {
      "login": "minrk",
      "id": 151929,
      "node_id": "MDQ6VXNlcjE1MTkyOQ==",
      "avatar_url": "https://avatars1.githubusercontent.com/u/151929?v=4",
      "gravatar_id": "",
      "url": "https://api.github.com/users/minrk",
      "html_url": "https://github.com/minrk",
      "followers_url": "https://api.github.com/users/minrk/followers",
      "following_url": "https://api.github.com/users/minrk/following{/other_user}",
      "gists_url": "https://api.github.com/users/minrk/gists{/gist_id}",
      "starred_url": "https://api.github.com/users/minrk/starred{/owner}{/repo}",
      "subscriptions_url": "https://api.github.com/users/minrk/subscriptions",
      "organizations_url": "https://api.github.com/users/minrk/orgs",
      "repos_url": "https://api.github.com/users/minrk/repos",
      "events_url": "https://api.github.com/users/minrk/events{/privacy}",
      "received_events_url": "https://api.github.com/users/minrk/received_events",
      "type": "User",
      "site_admin": false
    },
    "created_at": "2015-06-09T19:06:39Z",
    "updated_at": "2015-06-09T19:06:39Z",
    "author_association": "MEMBER",
    "body": "And `ls -l /usr/local/bin/python`\n"
  },
  {
    "url": "https://api.github.com/repos/ipython/ipython/issues/comments/110479086",
    "html_url": "https://github.com/ipython/ipython/issues/7947#issuecomment-110479086",
    "issue_url": "https://api.github.com/repos/ipython/ipython/issues/7947",
    "id": 110479086,
    "node_id": "MDEyOklzc3VlQ29tbWVudDExMDQ3OTA4Ng==",
    "user": {
      "login": "cel4",
      "id": 3819470,
      "node_id": "MDQ6VXNlcjM4MTk0NzA=",
      "avatar_url": "https://avatars1.githubusercontent.com/u/3819470?v=4",
      "gravatar_id": "",
      "url": "https://api.github.com/users/cel4",
      "html_url": "https://github.com/cel4",
      "followers_url": "https://api.github.com/users/cel4/followers",
      "following_url": "https://api.github.com/users/cel4/following{/other_user}",
      "gists_url": "https://api.github.com/users/cel4/gists{/gist_id}",
      "starred_url": "https://api.github.com/users/cel4/starred{/owner}{/repo}",
      "subscriptions_url": "https://api.github.com/users/cel4/subscriptions",
      "organizations_url": "https://api.github.com/users/cel4/orgs",
      "repos_url": "https://api.github.com/users/cel4/repos",
      "events_url": "https://api.github.com/users/cel4/events{/privacy}",
      "received_events_url": "https://api.github.com/users/cel4/received_events",
      "type": "User",
      "site_admin": false
    },
    "created_at": "2015-06-09T19:35:46Z",
    "updated_at": "2015-06-09T19:36:15Z",
    "author_association": "CONTRIBUTOR",
    "body": "I don't think it's a symlink issue. This here prints the expected path:\n\n``` python\nimport subprocess\nfrom subprocess import Popen\ncmd = [\n    '/usr/local/bin/python',\n    '-c', 'import sys;print(sys.path)',\n]\np = Popen(cmd, stdout=subprocess.PIPE, stderr=subprocess.PIPE)\nout, err = p.communicate()\nprint(out.decode(\"utf-8\"))\n```\n\n> ['', '/usr/local/Cellar/python/2.7.10/Frameworks/Python.framework/Versions/2.7/lib/python2.7/site-packages/setuptools-17.0-py2.7.egg', '/usr/local/Cellar/python/2.7.10/Frameworks/Python.framework/Versions/2.7/lib/python2.7/site-packages/pip-7.0.1-py2.7.egg', '/usr/local/Cellar/python/2.7.10/Frameworks/Python.framework/Versions/2.7/lib/python27.zip', '/usr/local/Cellar/python/2.7.10/Frameworks/Python.framework/Versions/2.7/lib/python2.7', '/usr/local/Cellar/python/2.7.10/Frameworks/Python.framework/Versions/2.7/lib/python2.7/plat-darwin', '/usr/local/Cellar/python/2.7.10/Frameworks/Python.framework/Versions/2.7/lib/python2.7/plat-mac', '/usr/local/Cellar/python/2.7.10/Frameworks/Python.framework/Versions/2.7/lib/python2.7/plat-mac/lib-scriptpackages', '/usr/local/Cellar/python/2.7.10/Frameworks/Python.framework/Versions/2.7/lib/python2.7/lib-tk', '/usr/local/Cellar/python/2.7.10/Frameworks/Python.framework/Versions/2.7/lib/python2.7/lib-old', '/usr/local/Cellar/python/2.7.10/Frameworks/Python.framework/Versions/2.7/lib/python2.7/lib-dynload', '/usr/local/Cellar/python/2.7.10/Frameworks/Python.framework/Versions/2.7/lib/python2.7/site-packages', '/usr/local/Cellar/python/2.7.10/Frameworks/Python.framework/Versions/2.7/lib/python2.7/site-packages/gtk-2.0', '/Library/Python/2.7/site-packages']\n\n`$ file /usr/local/bin/python` --> `/usr/local/bin/python: Mach-O 64-bit executable x86_64`\n`ls -l /usr/local/bin/python` -->  `4 lrwxr-xr-x 1 ch admin 34 Jun  5 22:03 /usr/local/bin/python -> ../Cellar/python/2.7.10/bin/python`\n"
  },
  {
    "url": "https://api.github.com/repos/ipython/ipython/issues/comments/110501378",
    "html_url": "https://github.com/ipython/ipython/issues/7947#issuecomment-110501378",
    "issue_url": "https://api.github.com/repos/ipython/ipython/issues/7947",
    "id": 110501378,
    "node_id": "MDEyOklzc3VlQ29tbWVudDExMDUwMTM3OA==",
    "user": {
      "login": "takluyver",
      "id": 327925,
      "node_id": "MDQ6VXNlcjMyNzkyNQ==",
      "avatar_url": "https://avatars3.githubusercontent.com/u/327925?v=4",
      "gravatar_id": "",
      "url": "https://api.github.com/users/takluyver",
      "html_url": "https://github.com/takluyver",
      "followers_url": "https://api.github.com/users/takluyver/followers",
      "following_url": "https://api.github.com/users/takluyver/following{/other_user}",
      "gists_url": "https://api.github.com/users/takluyver/gists{/gist_id}",
      "starred_url": "https://api.github.com/users/takluyver/starred{/owner}{/repo}",
      "subscriptions_url": "https://api.github.com/users/takluyver/subscriptions",
      "organizations_url": "https://api.github.com/users/takluyver/orgs",
      "repos_url": "https://api.github.com/users/takluyver/repos",
      "events_url": "https://api.github.com/users/takluyver/events{/privacy}",
      "received_events_url": "https://api.github.com/users/takluyver/received_events",
      "type": "User",
      "site_admin": false
    },
    "created_at": "2015-06-09T20:54:34Z",
    "updated_at": "2015-06-09T20:54:34Z",
    "author_association": "MEMBER",
    "body": "Then I'm completely mystified. The error message you showed above is clearly coming from a different interpreter.\n"
  },
  {
    "url": "https://api.github.com/repos/ipython/ipython/issues/comments/112235153",
    "html_url": "https://github.com/ipython/ipython/issues/7947#issuecomment-112235153",
    "issue_url": "https://api.github.com/repos/ipython/ipython/issues/7947",
    "id": 112235153,
    "node_id": "MDEyOklzc3VlQ29tbWVudDExMjIzNTE1Mw==",
    "user": {
      "login": "paulperry",
      "id": 501736,
      "node_id": "MDQ6VXNlcjUwMTczNg==",
      "avatar_url": "https://avatars1.githubusercontent.com/u/501736?v=4",
      "gravatar_id": "",
      "url": "https://api.github.com/users/paulperry",
      "html_url": "https://github.com/paulperry",
      "followers_url": "https://api.github.com/users/paulperry/followers",
      "following_url": "https://api.github.com/users/paulperry/following{/other_user}",
      "gists_url": "https://api.github.com/users/paulperry/gists{/gist_id}",
      "starred_url": "https://api.github.com/users/paulperry/starred{/owner}{/repo}",
      "subscriptions_url": "https://api.github.com/users/paulperry/subscriptions",
      "organizations_url": "https://api.github.com/users/paulperry/orgs",
      "repos_url": "https://api.github.com/users/paulperry/repos",
      "events_url": "https://api.github.com/users/paulperry/events{/privacy}",
      "received_events_url": "https://api.github.com/users/paulperry/received_events",
      "type": "User",
      "site_admin": false
    },
    "created_at": "2015-06-15T23:14:09Z",
    "updated_at": "2015-06-15T23:14:09Z",
    "author_association": "NONE",
    "body": "I have this problem on Mac OSX 10.9.5 and have a bit more information:  I get the error if I start the ipython notebook within the python 2.7 (non)environment, and I DON'T get the error if I start in the python3 environment.  I generate the error by opening the notebook and switching the kernel from within the notebook.  I have no PYTHONHOME env variable set .  This definitely seems like an environment issue.\n\nBelow is the full context.  I installed Anaconda-2.2.0-MacOSX-x86_64.pkg (having previously `mv anaconda oldconda`) . \n\n```\n~>which python\n/Users/paulperry/anaconda/bin/python\nPython 2.7.10 |Anaconda 2.2.0 (x86_64)| (default, May 28 2015, 17:04:42) \n~>python\nPython 2.7.10 |Anaconda 2.2.0 (x86_64)| (default, May 28 2015, 17:04:42) \n[GCC 4.2.1 (Apple Inc. build 5577)] on darwin\nType \"help\", \"copyright\", \"credits\" or \"license\" for more information.\nAnaconda is brought to you by Continuum Analytics.\nPlease check out: http://continuum.io/thanks and https://binstar.org\n>>> quit()\n~> conda create -n py3 python=3 anaconda\n~> [...]\n~> source activate py3\ndiscarding /Users/paulperry/anaconda/bin from PATH\nprepending /Users/paulperry/anaconda/envs/py3/bin to PATH\n(py3)~>python\nPython 3.3.5 |Anaconda 2.2.0 (x86_64)| (default, Sep  2 2014, 13:57:31) \n[GCC 4.2.1 (Apple Inc. build 5577)] on darwin\nType \"help\", \"copyright\", \"credits\" or \"license\" for more information.\n>>> quit()\n(py3)~> ipython kernelspec install-self --user\n(py3)~> source deactivate\ndiscarding /Users/paulperry/anaconda/envs/py3/bin from PATH\n~> ipython kernelspec install-self --user\n~>ls ~/.ipython/kernels/\npython2 python3\n~>\n~>cat ~/.ipython/kernels/python2/kernel.json \n{\n \"display_name\": \"Python 2\", \n \"language\": \"python\", \n \"argv\": [\n  \"/Users/paulperry/anaconda/bin/python\", \n  \"-m\", \n  \"IPython.kernel\", \n  \"-f\", \n  \"{connection_file}\"\n ]\n}~>cat ~/.ipython/kernels/python3/kernel.json \n{\n \"display_name\": \"Python 3\", \n \"language\": \"python\", \n \"argv\": [\n  \"/Users/paulperry/anaconda/envs/py3/bin/python\", \n  \"-m\", \n  \"IPython.kernel\", \n  \"-f\", \n  \"{connection_file}\"\n ]\n}~>\n}~>ipython notebook\n[I 19:07:31.011 NotebookApp] Using existing profile dir: u'/Users/paulperry/.ipython/profile_default'\n[I 19:07:31.014 NotebookApp] Using MathJax from CDN: https://cdn.mathjax.org/mathjax/latest/MathJax.js\n[I 19:07:31.040 NotebookApp] The port 8888 is already in use, trying another random port.\n[I 19:07:31.049 NotebookApp] Serving notebooks from local directory: /Users/paulperry\n[I 19:07:31.049 NotebookApp] 0 active kernels \n[I 19:07:31.049 NotebookApp] The IPython Notebook is running at: http://localhost:8889/\n[I 19:07:31.049 NotebookApp] Use Control-C to stop this server and shut down all kernels (twice to skip confirmation).\n[W 19:07:46.499 NotebookApp] Notebook Untitled.ipynb is not trusted\n[I 19:07:46.639 NotebookApp] Kernel started: 33aec8f1-a04c-4cbf-adc1-060e06c1dc62\n[I 19:07:51.048 NotebookApp] Kernel shutdown: 33aec8f1-a04c-4cbf-adc1-060e06c1dc62\n[I 19:07:51.061 NotebookApp] Kernel started: 83562e3a-0b48-4ad1-8434-d43605575545\nCould not find platform independent libraries <prefix>\nCould not find platform dependent libraries <exec_prefix>\nConsider setting $PYTHONHOME to <prefix>[:<exec_prefix>]\nFatal Python error: Py_Initialize: unable to load the file system codec\nImportError: No module named 'encodings'\n[I 19:07:54.061 NotebookApp] KernelRestarter: restarting kernel (1/5)\nCould not find platform independent libraries <prefix>\nCould not find platform dependent libraries <exec_prefix>\nConsider setting $PYTHONHOME to <prefix>[:<exec_prefix>]\nFatal Python error: Py_Initialize: unable to load the file system codec\nImportError: No module named 'encodings'\n[I 19:07:57.067 NotebookApp] KernelRestarter: restarting kernel (2/5)\nCould not find platform independent libraries <prefix>\nCould not find platform dependent libraries <exec_prefix>\nConsider setting $PYTHONHOME to <prefix>[:<exec_prefix>]\nFatal Python error: Py_Initialize: unable to load the file system codec\nImportError: No module named 'encodings'\n[I 19:08:00.071 NotebookApp] KernelRestarter: restarting kernel (3/5)\nCould not find platform independent libraries <prefix>\nCould not find platform dependent libraries <exec_prefix>\nConsider setting $PYTHONHOME to <prefix>[:<exec_prefix>]\nFatal Python error: Py_Initialize: unable to load the file system codec\nImportError: No module named 'encodings'\n[W 19:08:01.067 NotebookApp] Timeout waiting for kernel_info reply from 83562e3a-0b48-4ad1-8434-d43605575545\n[I 19:08:03.076 NotebookApp] KernelRestarter: restarting kernel (4/5)\nWARNING:root:kernel 83562e3a-0b48-4ad1-8434-d43605575545 restarted\nCould not find platform independent libraries <prefix>\nCould not find platform dependent libraries <exec_prefix>\nConsider setting $PYTHONHOME to <prefix>[:<exec_prefix>]\nFatal Python error: Py_Initialize: unable to load the file system codec\nImportError: No module named 'encodings'\n[W 19:08:06.083 NotebookApp] KernelRestarter: restart failed\n[W 19:08:06.083 NotebookApp] Kernel 83562e3a-0b48-4ad1-8434-d43605575545 died, removing from map.\nERROR:root:kernel 83562e3a-0b48-4ad1-8434-d43605575545 restarted failed!\n[W 19:08:06.092 NotebookApp] Kernel deleted before session\n[W 19:08:06.092 NotebookApp] 410 DELETE /api/sessions/61b30c52-7c4d-45b1-8b77-6c2a3ccf3eac (::1) 0.89ms referer=http://localhost:8889/notebooks/Untitled.ipynb\n^C[I 19:12:30.925 NotebookApp] interrupted\nServing notebooks from local directory: /Users/paulperry\n0 active kernels \nThe IPython Notebook is running at: http://localhost:8889/\nShutdown this notebook server (y/[n])? y\n[C 19:12:32.613 NotebookApp] Shutdown confirmed\n[I 19:12:32.613 NotebookApp] Shutting down kernels\n~>source activate py3\ndiscarding /Users/paulperry/anaconda/bin from PATH\nprepending /Users/paulperry/anaconda/envs/py3/bin to PATH\n(py3)~>ipython notebook\n[I 19:12:49.112 NotebookApp] Using existing profile dir: '/Users/paulperry/.ipython/profile_default'\n[I 19:12:49.117 NotebookApp] Using MathJax from CDN: https://cdn.mathjax.org/mathjax/latest/MathJax.js\n[I 19:12:49.149 NotebookApp] The port 8888 is already in use, trying another random port.\n[I 19:12:49.159 NotebookApp] Serving notebooks from local directory: /Users/paulperry\n[I 19:12:49.159 NotebookApp] 0 active kernels \n[I 19:12:49.160 NotebookApp] The IPython Notebook is running at: http://localhost:8889/\n[I 19:12:49.160 NotebookApp] Use Control-C to stop this server and shut down all kernels (twice to skip confirmation).\n[W 19:12:53.769 NotebookApp] Notebook Untitled.ipynb is not trusted\n[I 19:12:53.901 NotebookApp] Kernel started: bffc4f3e-acff-440c-aedb-d5f3f0380077\n[I 19:12:57.874 NotebookApp] Kernel shutdown: bffc4f3e-acff-440c-aedb-d5f3f0380077\n[I 19:12:57.885 NotebookApp] Kernel started: ea0cb9d5-ff3e-48fc-aaff-452ff0833e8f\n\n```\n\nAll is good under the python3 environment !  This is really going to confuse new users of ipynb .  \n"
  }
]
