[
  {
    "url": "https://api.github.com/repos/ipython/ipython/issues/comments/87750149",
    "html_url": "https://github.com/ipython/ipython/issues/8197#issuecomment-87750149",
    "issue_url": "https://api.github.com/repos/ipython/ipython/issues/8197",
    "id": 87750149,
    "node_id": "MDEyOklzc3VlQ29tbWVudDg3NzUwMTQ5",
    "user": {
      "login": "takluyver",
      "id": 327925,
      "node_id": "MDQ6VXNlcjMyNzkyNQ==",
      "avatar_url": "https://avatars3.githubusercontent.com/u/327925?v=4",
      "gravatar_id": "",
      "url": "https://api.github.com/users/takluyver",
      "html_url": "https://github.com/takluyver",
      "followers_url": "https://api.github.com/users/takluyver/followers",
      "following_url": "https://api.github.com/users/takluyver/following{/other_user}",
      "gists_url": "https://api.github.com/users/takluyver/gists{/gist_id}",
      "starred_url": "https://api.github.com/users/takluyver/starred{/owner}{/repo}",
      "subscriptions_url": "https://api.github.com/users/takluyver/subscriptions",
      "organizations_url": "https://api.github.com/users/takluyver/orgs",
      "repos_url": "https://api.github.com/users/takluyver/repos",
      "events_url": "https://api.github.com/users/takluyver/events{/privacy}",
      "received_events_url": "https://api.github.com/users/takluyver/received_events",
      "type": "User",
      "site_admin": false
    },
    "created_at": "2015-03-30T16:57:45Z",
    "updated_at": "2015-03-30T16:57:45Z",
    "author_association": "MEMBER",
    "body": "Yes, I do - Python 3.4.3 made a small change to the tokenize module which caused some problems for us. I filed [an issue](http://bugs.python.org/issue23615) and it should be fixed when 3.4.4 comes out. So far we've only heard of the error occurring when running the tests, not in actual use, so we're not especially concerned about fixing it.\n"
  },
  {
    "url": "https://api.github.com/repos/ipython/ipython/issues/comments/90957841",
    "html_url": "https://github.com/ipython/ipython/issues/8197#issuecomment-90957841",
    "issue_url": "https://api.github.com/repos/ipython/ipython/issues/8197",
    "id": 90957841,
    "node_id": "MDEyOklzc3VlQ29tbWVudDkwOTU3ODQx",
    "user": {
      "login": "brannerchinese",
      "id": 549884,
      "node_id": "MDQ6VXNlcjU0OTg4NA==",
      "avatar_url": "https://avatars2.githubusercontent.com/u/549884?v=4",
      "gravatar_id": "",
      "url": "https://api.github.com/users/brannerchinese",
      "html_url": "https://github.com/brannerchinese",
      "followers_url": "https://api.github.com/users/brannerchinese/followers",
      "following_url": "https://api.github.com/users/brannerchinese/following{/other_user}",
      "gists_url": "https://api.github.com/users/brannerchinese/gists{/gist_id}",
      "starred_url": "https://api.github.com/users/brannerchinese/starred{/owner}{/repo}",
      "subscriptions_url": "https://api.github.com/users/brannerchinese/subscriptions",
      "organizations_url": "https://api.github.com/users/brannerchinese/orgs",
      "repos_url": "https://api.github.com/users/brannerchinese/repos",
      "events_url": "https://api.github.com/users/brannerchinese/events{/privacy}",
      "received_events_url": "https://api.github.com/users/brannerchinese/received_events",
      "type": "User",
      "site_admin": false
    },
    "created_at": "2015-04-08T15:52:28Z",
    "updated_at": "2015-04-08T15:52:28Z",
    "author_association": "NONE",
    "body": "Are we speaking about the error\n\n```\nopen() takes 1 positional argument but 2 were given\n```\n\n? I've encountered it while following https://github.com/jakevdp/sklearn_pycon2015, as soon as matplotlib is first called within a notebook.\n"
  },
  {
    "url": "https://api.github.com/repos/ipython/ipython/issues/comments/90960984",
    "html_url": "https://github.com/ipython/ipython/issues/8197#issuecomment-90960984",
    "issue_url": "https://api.github.com/repos/ipython/ipython/issues/8197",
    "id": 90960984,
    "node_id": "MDEyOklzc3VlQ29tbWVudDkwOTYwOTg0",
    "user": {
      "login": "takluyver",
      "id": 327925,
      "node_id": "MDQ6VXNlcjMyNzkyNQ==",
      "avatar_url": "https://avatars3.githubusercontent.com/u/327925?v=4",
      "gravatar_id": "",
      "url": "https://api.github.com/users/takluyver",
      "html_url": "https://github.com/takluyver",
      "followers_url": "https://api.github.com/users/takluyver/followers",
      "following_url": "https://api.github.com/users/takluyver/following{/other_user}",
      "gists_url": "https://api.github.com/users/takluyver/gists{/gist_id}",
      "starred_url": "https://api.github.com/users/takluyver/starred{/owner}{/repo}",
      "subscriptions_url": "https://api.github.com/users/takluyver/subscriptions",
      "organizations_url": "https://api.github.com/users/takluyver/orgs",
      "repos_url": "https://api.github.com/users/takluyver/repos",
      "events_url": "https://api.github.com/users/takluyver/events{/privacy}",
      "received_events_url": "https://api.github.com/users/takluyver/received_events",
      "type": "User",
      "site_admin": false
    },
    "created_at": "2015-04-08T16:06:13Z",
    "updated_at": "2015-04-08T16:06:13Z",
    "author_association": "MEMBER",
    "body": "Yep, that's the one. _sigh_\n\nI'm at PyCon, I'll try to get an estimate of when 3.4.4 might be out.\n"
  },
  {
    "url": "https://api.github.com/repos/ipython/ipython/issues/comments/316500507",
    "html_url": "https://github.com/ipython/ipython/issues/8197#issuecomment-316500507",
    "issue_url": "https://api.github.com/repos/ipython/ipython/issues/8197",
    "id": 316500507,
    "node_id": "MDEyOklzc3VlQ29tbWVudDMxNjUwMDUwNw==",
    "user": {
      "login": "Carreau",
      "id": 335567,
      "node_id": "MDQ6VXNlcjMzNTU2Nw==",
      "avatar_url": "https://avatars3.githubusercontent.com/u/335567?v=4",
      "gravatar_id": "",
      "url": "https://api.github.com/users/Carreau",
      "html_url": "https://github.com/Carreau",
      "followers_url": "https://api.github.com/users/Carreau/followers",
      "following_url": "https://api.github.com/users/Carreau/following{/other_user}",
      "gists_url": "https://api.github.com/users/Carreau/gists{/gist_id}",
      "starred_url": "https://api.github.com/users/Carreau/starred{/owner}{/repo}",
      "subscriptions_url": "https://api.github.com/users/Carreau/subscriptions",
      "organizations_url": "https://api.github.com/users/Carreau/orgs",
      "repos_url": "https://api.github.com/users/Carreau/repos",
      "events_url": "https://api.github.com/users/Carreau/events{/privacy}",
      "received_events_url": "https://api.github.com/users/Carreau/received_events",
      "type": "User",
      "site_admin": false
    },
    "created_at": "2017-07-19T20:03:39Z",
    "updated_at": "2017-07-19T20:03:39Z",
    "author_association": "MEMBER",
    "body": "Hi, \r\n\r\nThis issue has been quiet for almost 2 years, and I don't think there is anything we can do. It has been marked as no-action, and I'm going to close it to attempt to reduce the number of opened issue. Feel free to reopen if needed. \r\n\r\nThanks. "
  }
]
